Workbook
Name rev_int: Inputs!$B$6
Name inst_int: Inputs!$B$7
Name upfront: Inputs!$B$8
Name late: Inputs!$B$9
Name interchange: Inputs!$B$10
Name avg_rec: Inputs!$B$13
Name bal_rev: Inputs!$B$15
Name bal_tra: Inputs!$B$16
Name bal_inst: Inputs!$B$17
Name bal_tot: Inputs!$B$18
Name orig: Inputs!$B$21
Name L_life16: Inputs!$B$24
Name L_life90: Inputs!$B$25
Name L_v2_16: Inputs!$B$26
Name L_v2_90: Inputs!$B$27
Name b181_jun: Inputs!$B$30
Name b181_sep: Inputs!$B$31
Name coupon: Inputs!$B$33
Name advance: Inputs!$B$34

Sheet Inputs
A1: Facility yield analysis — inputs (Today = September 2026)
A2: Yellow cells are inputs; every one cites its source. PHP unless stated. Facility assumptions at the bottom are the only free assumptions.
A4: Input | B4: Value | C4: Unit | D4: Source | E4: Notes
A5: REVENUE — September 2026
A6: Revolving interest (finance charge) | B6: 2229680 | C6: PHP/mo | D6: KPI Dashboard_v2026 (12), Monthly r55, Sep 2026 | E6: Statement-billed; warehouse balances report shows ₱2,235,956 for the same cycles (0.3% diff, cycle vs calendar)
A7: Installment interest | B7: 486325 | C7: PHP/mo | D7: KPI Dashboard Monthly r52, Sep 2026
A8: Installment upfront fees | B8: 439734 | C8: PHP/mo | D8: KPI Dashboard Monthly r53, Sep 2026
A9: Late payment fees | B9: 126426 | C9: PHP/mo | D9: KPI Dashboard Monthly r49, Sep 2026
A10: Interchange fee income | B10: 2630890 | C10: PHP/mo | D10: KPI Dashboard Monthly r42, Sep 2026 | E10: Gross, merchant-side (i2c Network Settlement Summary); never posts to cardholder accounts
A11: Total revenue (check) | B11: 5913055 | C11: PHP/mo | D11: KPI Dashboard Monthly r40, Sep 2026 | E11: =sum of the five lines above
A12: BALANCES — September 2026
A13: Average receivables (denominator) | B13: 211159157 | C13: PHP | D13: KPI Dashboard Monthly r67 'Total Loans Outstanding (average)', Sep 2026 | E13: Used as the yield denominator throughout
A14: End-of-month receivables | B14: 232895128 | C14: PHP | D14: KPI Dashboard Monthly r65, Sep 2026 | E14: Reference only
A15: Revolving balance (statements with interest) | B15: 91366063 | C15: PHP | D15: revolver_transactor_balances_2026-01_to_2026-09_10262026.csv, all_revolving, 2026-09 | E15: Statement-based; ending balance less installment charge on statements with interest_charged > 0
A16: Transacting balance | B16: 83462733 | C16: PHP | D16: same file, all_transacting, 2026-09 | E16: Ending balance less installment charge on statements with no interest
A17: Installment balance | B17: 33428938 | C17: PHP | D17: same file, all_installment, 2026-09 | E17: Future principal + this cycle's installment charge
A18: Total (three buckets) | B18: 208257733 | C18: PHP | D18: same file, all_total, 2026-09 | E18: Differs from r67 only by definition (statement cycle vs calendar average)
A19: Of revolving balance, 180+ DPD | B19: 17653522 | C19: PHP | D19: same file, removed_180dpd_ending_balance, 2026-09 | E19: all_revolving − x180_revolving; transacting x180 ≈ all → losses sit in the revolving bucket
A20: ORIGINATIONS / TURNOVER
A21: Principal originated, Sep 2026 | B21: 1.6022121e+08 | C21: PHP/mo | D21: vintage_loss_by_origination_month_10262026.csv, originated_principal_php, 2026-09 | E21: Net of refunds/chargebacks and cancelled-plan re-adds (FIFO waterfall view)
A22: Settlement volume, Sep 2026 (reference) | B22: 190860992 | C22: PHP/mo | D22: KPI Dashboard Monthly r127, Sep 2026 | E22: Gross settlements less returns; higher than originated principal by definition
A23: LOSS RATES — on originated principal (seasoned, cumulative since month shown)
A24: Lifetime, >15 DPD | B24: 0.01781 | C24: ratio | D24: vintage_loss_since_origination_month_10262026.csv, since 2024-01, loss_rate_16dpd_seasoned_pct = 1.781% | E24: Delinquent principal ÷ seasoned originated principal, all vintages Jan 2024–Sep 2026
A25: Lifetime, ≥90 DPD | B25: 0.01459 | C25: ratio | D25: same file, since 2024-01, loss_rate_90dpd_seasoned_pct = 1.459% | E25: Conservative case: fully seasoned 'has gone bad' measure across all vintages incl. V1-model 2025
A26: Since Jan 2026 (V2 model), >15 DPD | B26: 0.01559 | C26: ratio | D26: same file, since 2026-01, loss_rate_16dpd_seasoned_pct = 1.559% | E26: Young vintages will rise with seasoning — read as a floor
A27: Since Jan 2026 (V2 model), ≥90 DPD | B27: 0.01059 | C27: ratio | D27: same file, since 2026-01, loss_rate_90dpd_seasoned_pct = 1.059% | E27: BASE CASE (Steve, 2026-10-26): V2 model from Dec 2025; go-forward baseline. Young vintages — will rise with seasoning; >15 DPD for the same window is 1.559%
A28: Since Oct 2025 (worst vintages), ≥90 DPD | B28: 0.01497 | C28: ratio | D28: same file, since 2025-10, loss_rate_90dpd_seasoned_pct = 1.497% | E28: Oct 2025–Jan 2026 vintages are the historical worst (2.5–4.1% >15 DPD)
A29: CROSS-CHECK — dashboard 181+ bucket
A30: 181+ DPD balance, Jun 2026 | B30: 10636807 | C30: PHP | D30: KPI Dashboard Monthly r84, Jun 2026 | E30: Nothing written off; bucket growth = gross roll to terminal delinquency
A31: 181+ DPD balance, Sep 2026 | B31: 16174268 | C31: PHP | D31: KPI Dashboard Monthly r84, Sep 2026
A32: FACILITY ASSUMPTIONS
A33: Coupon (all-in interest rate on drawn amount) | B33: 0.19 | C33: ratio | D33: Assumption — Steve, 2026-10-26 ('high teens') | E33: Frictions (PH withholding, FX hedge) deliberately excluded for now
A34: Advance rate (drawn ÷ eligible receivables) | B34: 0.8 | C34: ratio | D34: Assumption — market range 75–85% (structure note §3.3) | E34: Cost of funds on receivables = coupon × advance rate
A35: FX PHP per USD | B35: 55.8 | C35: ratio | D35: KPI Dashboard Monthly r2 'Forex' | E35: Display only

Sheet Today — Sep 2026
A1: Yield on average receivables — September 2026, annualized (monthly × 12, simple)
A3: Line | B3: PHP / month | C3: ÷ avg receivables = monthly % | D3: × 12 = annualized | E3: Comment
A4: Revolving interest | B4: =rev_int | C4: =B4/avg_rec | D4: =C4*12 | E4: Billed on statements → paid into the collection account
A5: Installment interest + upfront fees | B5: =inst_int+upfront | C5: =B5/avg_rec | D5: =C5*12 | E5: Billed on statements → collection account
A6: Late payment fees | B6: =late | C6: =B6/avg_rec | D6: =C6*12 | E6: Billed on statements → collection account
A7: BALANCE-DRIVEN YIELD (collateral cash flows) | B7: =B4+B5+B6 | C7: =B7/avg_rec | D7: =C7*12 | E7: Everything a lender sees in pledged collections
A8: Interchange | B8: =interchange | C8: =B8/avg_rec | D8: =C8*12 | E8: Settled by Mastercard to Zed at T+1 on the merchant side; not a cardholder payment
A9: ALL-REVENUE YIELD | B9: =B7+B8 | C9: =B9/avg_rec | D9: =C9*12
A11: LOSS ON RECEIVABLES — three citable measures
A12: Measure | B12: Loss ÷ originations | C12: × annual originations ÷ avg receivables (turnover) | D12: =annualized loss on receivables | E12: How it is built
A13: Principal turnover (Sep originations × 12 ÷ avg receivables) | C13: =orig*12/avg_rec | E13: Pesos lent per year per peso outstanding; falls as revolvers hold balances
A14: A. Lifetime vintage loss, ≥90 DPD (conservative) | B14: =L_life90 | C14: =C13 | D14: =B14*C14 | E14: Seasoned delinquent principal ≥90 DPD ÷ seasoned originated principal, all vintages; × turnover
A15: B. Lifetime vintage loss, >15 DPD (upper) | B15: =L_life16 | C15: =C13 | D15: =B15*C15 | E15: Same, >15 DPD — includes early-stage delinquency that may still cure
A16: C. V2-model vintages since Jan 2026, ≥90 DPD (BASE CASE) | B16: =L_v2_90 | C16: =C13 | D16: =B16*C16 | E16: Base case per Steve 2026-10-26: V2 model rolled out Dec 2025 with a visible break in delinquency; treated as the go-forward baseline. Caveat: vintages ≤9 months old — the ≥90 DPD rate will rise as they season (the >15 DPD rate for the same window is 1.56%).
A17: D. Cross-check: dashboard 181+ bucket growth Jun→Sep, annualized | B17: =(b181_sep-b181_jun)/3 | C17: PHP/month → | D17: =B17*12/avg_rec | E17: Not a vintage measure; what actually rolled to 181+ in the last three months, on today's book
A19: NET YIELD AND EXCESS SPREAD (base case = loss C, V2 vintages)
B20: Balance-driven view (collateral only) | C20: All-revenue view (incl. interchange) | E20: Comment
A21: Gross yield | B21: =D7 | C21: =D9
A22: − Loss on receivables (C, V2 vintages) | B22: =D16 | C22: =D16 | E22: Same loss either way — it is a loss of principal
A23: =Net yield (before servicing/opex) | B23: =B21-B22 | C23: =C21-C22
A24: − Cost of funds on receivables = coupon × advance rate | B24: =coupon*advance | C24: =coupon*advance | E24: 19% × 80% = 15.2 points; no withholding or hedge included
A25: =Excess spread | B25: =B23-B24 | C25: =C23-C24 | E25: Negative in the collateral-only view: the facility is being underwritten on interchange + corporate recourse
A26: Sensitivity: excess spread at the conservative lifetime ≥90 DPD loss (A) | B26: =B25-(D14-D16) | C26: =C25-(D14-D16) | E26: Difference between A and C is the entire V1→V2 narrative; a lender will ask for both
A27: BUCKET VIEW (monthly yield on each bucket's own balance — reconciles to Steve's BOE sheet)
A28: Bucket | B28: Balance (PHP) | C28: Share of total | D28: Revenue on this bucket, PHP/mo | E28: Monthly yield on own balance
A29: Revolving | B29: =bal_rev | C29: =B29/bal_tot | D29: =rev_int | E29: =D29/B29
A30: Installment | B30: =bal_inst | C30: =B30/bal_tot | D30: =inst_int+upfront | E30: =D30/B30
A31: Transacting (interchange only) | B31: =bal_tra | C31: =B31/bal_tot | D31: =interchange | E31: =D31/B31
A32: Note: interchange is earned on spend, not balances; 3.15%/mo on the transacting bucket only because those balances turn ~2.3× a month. On the whole book it is 1.26%/mo.

Sheet Collateral-only view
A1: Why the collateral-only view is 8.2% net — and why it matters for structure
A3: In configuration A (parent borrows; ZFPI grants a lien over the receivables pool + control of the collection account), the lender's security is the cash cardholders pay against their statements.
A4: Cardholder payments = statement balance = purchases + revolving interest + installment interest + upfront fees + late fees. The revenue inside those payments is the three interest/fee lines — 'balance-driven yield'.
A5: Interchange is paid by Mastercard to Zed at settlement (T+1), netted against what Zed funds to the merchant. It is never billed to a cardholder and never enters the collection account. A lender can only count it through recourse to Zed (guarantee / corporate covenant), not through the pledged asset.
A7: Collateral-only arithmetic (Sep 2026, annualized on avg receivables):
A9: Revolving interest | B9: ='Today — Sep 2026'!D4
A10: Installment interest + upfront fees | B10: ='Today — Sep 2026'!D5
A11: Late fees | B11: ='Today — Sep 2026'!D6
A12: =Balance-driven gross yield | B12: ='Today — Sep 2026'!D7
A13: − Loss on receivables (base case C, V2 vintages) | B13: ='Today — Sep 2026'!D16
A14: =Net collateral yield | B14: =B12-B13
A15: − Cost of funds (coupon × advance) | B15: =coupon*advance
A16: =Excess spread, collateral only | B16: =B14-B15
A18: Reading: on pledged cash flows alone, today's book does not carry a high-teens coupon. The facility is therefore underwritten on interchange plus corporate recourse — which is why the parent guarantee is not negotiable away on a first facility, and why negotiation capital is better spent on the coupon.
A19: The All-revenue column on the Today sheet is the same arithmetic with interchange included.

Sheet Scenarios
A1: Scenario analysis — excess spread (all-revenue view) by coupon × loss rate × revolving share
A2: Model: transacting and installment balances held at September levels; interchange, installment charges and late fees held in pesos (they are spend-driven); revolving balance scaled to hit the target share; revolving interest = Sep monthly rate on revolving balance; originations held → principal turnover falls as balances grow, so the same loss-on-originations becomes a smaller loss on balances. Cost of funds = coupon × advance rate; no frictions.
A4: Calibration (from Inputs)
A5: Revolving monthly rate on revolving balance | B5: =rev_int/bal_rev
A6: Revolving share of balances, today | B6: =bal_rev/bal_tot
A7: Non-revolving balance (transacting + installment), scaled to avg receivables | B7: =(bal_tra+bal_inst)/bal_tot*avg_rec
A8: Annual originations (Sep × 12) | B8: =orig*12
A9: Annual interchange + installment charges + late fees (Sep × 12) | B9: =(interchange+inst_int+upfront+late)*12
A10: of which balance-driven (installment charges + late fees) | B10: =(inst_int+upfront+late)*12
A11: Advance rate | B11: =advance
A14: Revolving share of balances = Today (43.9%) | B14: =bal_rev/bal_tot
A15: Revolving balance (PHP) | B15: =$B$14/(1-$B$14)*$B$7
A16: Total receivables (PHP) | B16: =$B$7+$B$15
A17: Gross yield — all revenue | B17: =($B$5*12*$B$15+$B$9)/$B$16
A18: Gross yield — balance-driven only | B18: =($B$5*12*$B$15+$B$10)/$B$16
A19: Principal turnover (x per year) | B19: =$B$8/$B$16
A20: Excess spread (all-revenue) — coupon ↓ / loss rate → | B20: V2 ≥90 DPD 1.06% | C20: Lifetime ≥90 DPD 1.46% | D20: Lifetime >15 DPD 1.78% | F20: Net yield (before cost) → | G20: V2 ≥90 DPD 1.06% | H20: Lifetime ≥90 DPD 1.46% | I20: Lifetime >15 DPD 1.78%
A21: Coupon 15% (cost on receivables = 15% × advance) | B21: =$B$17-L_v2_90*$B$19-0.15*$B$11 | C21: =$B$17-L_life90*$B$19-0.15*$B$11 | D21: =$B$17-L_life16*$B$19-0.15*$B$11 | G21: =$B$17-L_v2_90*$B$19 | H21: =$B$17-L_life90*$B$19 | I21: =$B$17-L_life16*$B$19
A22: Coupon 17% (cost on receivables = 17% × advance) | B22: =$B$17-L_v2_90*$B$19-0.17*$B$11 | C22: =$B$17-L_life90*$B$19-0.17*$B$11 | D22: =$B$17-L_life16*$B$19-0.17*$B$11 | G22: =$B$17-L_v2_90*$B$19 | H22: =$B$17-L_life90*$B$19 | I22: =$B$17-L_life16*$B$19
A23: Coupon 19% (cost on receivables = 19% × advance) | B23: =$B$17-L_v2_90*$B$19-0.19*$B$11 | C23: =$B$17-L_life90*$B$19-0.19*$B$11 | D23: =$B$17-L_life16*$B$19-0.19*$B$11 | G23: =$B$17-L_v2_90*$B$19 | H23: =$B$17-L_life90*$B$19 | I23: =$B$17-L_life16*$B$19
A25: Revolving share of balances = 50% | B25: 0.5
A26: Revolving balance (PHP) | B26: =$B$25/(1-$B$25)*$B$7
A27: Total receivables (PHP) | B27: =$B$7+$B$26
A28: Gross yield — all revenue | B28: =($B$5*12*$B$26+$B$9)/$B$27
A29: Gross yield — balance-driven only | B29: =($B$5*12*$B$26+$B$10)/$B$27
A30: Principal turnover (x per year) | B30: =$B$8/$B$27
A31: Excess spread (all-revenue) — coupon ↓ / loss rate → | B31: V2 ≥90 DPD 1.06% | C31: Lifetime ≥90 DPD 1.46% | D31: Lifetime >15 DPD 1.78% | F31: Net yield (before cost) → | G31: V2 ≥90 DPD 1.06% | H31: Lifetime ≥90 DPD 1.46% | I31: Lifetime >15 DPD 1.78%
A32: Coupon 15% (cost on receivables = 15% × advance) | B32: =$B$28-L_v2_90*$B$30-0.15*$B$11 | C32: =$B$28-L_life90*$B$30-0.15*$B$11 | D32: =$B$28-L_life16*$B$30-0.15*$B$11 | G32: =$B$28-L_v2_90*$B$30 | H32: =$B$28-L_life90*$B$30 | I32: =$B$28-L_life16*$B$30
A33: Coupon 17% (cost on receivables = 17% × advance) | B33: =$B$28-L_v2_90*$B$30-0.17*$B$11 | C33: =$B$28-L_life90*$B$30-0.17*$B$11 | D33: =$B$28-L_life16*$B$30-0.17*$B$11 | G33: =$B$28-L_v2_90*$B$30 | H33: =$B$28-L_life90*$B$30 | I33: =$B$28-L_life16*$B$30
A34: Coupon 19% (cost on receivables = 19% × advance) | B34: =$B$28-L_v2_90*$B$30-0.19*$B$11 | C34: =$B$28-L_life90*$B$30-0.19*$B$11 | D34: =$B$28-L_life16*$B$30-0.19*$B$11 | G34: =$B$28-L_v2_90*$B$30 | H34: =$B$28-L_life90*$B$30 | I34: =$B$28-L_life16*$B$30
A36: Revolving share of balances = 55% | B36: 0.55
A37: Revolving balance (PHP) | B37: =$B$36/(1-$B$36)*$B$7
A38: Total receivables (PHP) | B38: =$B$7+$B$37
A39: Gross yield — all revenue | B39: =($B$5*12*$B$37+$B$9)/$B$38
A40: Gross yield — balance-driven only | B40: =($B$5*12*$B$37+$B$10)/$B$38
A41: Principal turnover (x per year) | B41: =$B$8/$B$38
A42: Excess spread (all-revenue) — coupon ↓ / loss rate → | B42: V2 ≥90 DPD 1.06% | C42: Lifetime ≥90 DPD 1.46% | D42: Lifetime >15 DPD 1.78% | F42: Net yield (before cost) → | G42: V2 ≥90 DPD 1.06% | H42: Lifetime ≥90 DPD 1.46% | I42: Lifetime >15 DPD 1.78%
A43: Coupon 15% (cost on receivables = 15% × advance) | B43: =$B$39-L_v2_90*$B$41-0.15*$B$11 | C43: =$B$39-L_life90*$B$41-0.15*$B$11 | D43: =$B$39-L_life16*$B$41-0.15*$B$11 | G43: =$B$39-L_v2_90*$B$41 | H43: =$B$39-L_life90*$B$41 | I43: =$B$39-L_life16*$B$41
A44: Coupon 17% (cost on receivables = 17% × advance) | B44: =$B$39-L_v2_90*$B$41-0.17*$B$11 | C44: =$B$39-L_life90*$B$41-0.17*$B$11 | D44: =$B$39-L_life16*$B$41-0.17*$B$11 | G44: =$B$39-L_v2_90*$B$41 | H44: =$B$39-L_life90*$B$41 | I44: =$B$39-L_life16*$B$41
A45: Coupon 19% (cost on receivables = 19% × advance) | B45: =$B$39-L_v2_90*$B$41-0.19*$B$11 | C45: =$B$39-L_life90*$B$41-0.19*$B$11 | D45: =$B$39-L_life16*$B$41-0.19*$B$11 | G45: =$B$39-L_v2_90*$B$41 | H45: =$B$39-L_life90*$B$41 | I45: =$B$39-L_life16*$B$41
...

Sheet Sources
A1: Sources and how to regenerate
A3: KPI Dashboard_v2026 (12).xlsx, Monthly tab | B3: Steve's periodically updated KPI workbook; snapshot of 2026-10-26 filed at debt_dd/inbox/processed/. Rows cited by number on the Inputs sheet. Revenue lines from the i2c Transaction History Settlement Extract and Network Settlement Summary (see its KPIs Definition tab).
A4: revolver_transactor_balances_2026-01_to_2026-09_10262026.csv | B4: ~/apps/zed/Analysis+Reports/. Regenerate: bash ~/.claude/skills/revolver-transactor-report/scripts/run_report.sh --from 2026-01 --to 2026-09 (BigQuery epicac-2.zed_reporting views; definitions in the skill). Statement-based: revolving = ending balance less installment charge on statements with interest_charged > 0.
A5: vintage_loss_by_origination_month_10262026.csv / vintage_loss_since_origination_month_10262026.csv | B5: ~/apps/zed/Analysis+Reports/. Regenerate: bash ~/.claude/skills/vintage-loss-report/scripts/run_report.sh (FIFO waterfall views in epicac-2.zed_reporting). Run of 2026-10-26: waterfall vs actual 97.0% exact, 1.35% residual — PASS; delinquent-book tie 0.17% — PASS.
A6: Annualization | B6: Monthly amount ÷ September average receivables (Dashboard r67) × 12. Simple, not compounded — the same convention as Steve's BOE Yield sheet.
A7: Loss on receivables | B7: Loss-on-originations (vintage, seasoned, cumulative) × principal turnover (Sep originations × 12 ÷ avg receivables). Cross-checked against 181+ bucket growth on the dashboard, which is not a vintage measure.
A8: Excluded on purpose | B8: PH withholding on the intercompany coupon, FX hedge cost, servicing/opex, i2c processing cost, Mastercard network assessments. Add back before quoting an all-in number to a lender.
A9: Prepared | B9: 2026-10-26, debt_dd workspace; internal — not fund-facing.
