Workbook
Name ForEx: Monthly!$C$2
Name IQ_CH: 110000
Name IQ_CQ: 5000
Name IQ_CY: 10000
Name IQ_DAILY: 500000
Name IQ_FH: 100000
Name IQ_FQ: 500
Name IQ_FWD_CY: 10001
Name IQ_FWD_CY1: 10002
Name IQ_FWD_CY2: 10003
Name IQ_FWD_FY: 1001
Name IQ_FWD_FY1: 1002
Name IQ_FWD_FY2: 1003
Name IQ_FWD_Q: 501
Name IQ_FWD_Q1: 502
Name IQ_FWD_Q2: 503
Name IQ_FY: 1000
Name IQ_LATESTK: 1000
Name IQ_LATESTQ: 500
Name IQ_LTM: 2000
Name IQ_LTMMONTH: 120000
Name IQ_MONTH: 15000
Name IQ_NTM: 6000
Name IQ_TODAY: 0
Name IQ_WEEK: 50000
Name IQ_YTD: 3000
Name IQ_YTDMONTH: 130000

Sheet KPIs Definition
B2: KPI | C2: Definition | D2: Data Source
B3: Monthly Active Users (MAU) | C3: Customers that have generated revenue in the last 30 calendar days | D3: 1. i2cTransaction History Settlement Extract 2. Late Payment Fee Allocation 3. Wye Customer List (for user ID) 4. DFC file - date 01
B4: Monthly/Daily Transacting Users | C4: Customers that have at least 1 transaction in the last 30 calendar days/24 hours | D4: BQ
B5: Settlement Volume + Returns | C5: Gross Settlements - Returns Settlements in USD are translated to PHP using the actual average forex rate from Mastercard | D5: i2C, Network Settlement Summary
B6: Users | C6: Total number of cardholders in Open/Active status as of the end of the month. Does not include Closed accounts | D6: Wye Customer List
B7: Revolvers | C7: Number of accounts that have revolved the balance in the past 30 days | D7: i2C, SSRP_DFC File
B8: Interest-Earning Portfolio | C8: Total outstanding balance earning interest (including accounts that are past due) | D8: i2C, SSRP_DFC File
B9: Interchange Fee Income | C9: Interchange fee revenue earned from the merchant's side of each card transaction. Interchange fee revenue in USD is translated to PHP using the actual average forex rate from Mastercard | D9: i2C, Network Settlement Summary
B10: Late Payment Fee | C10: Late payment fees collected | D10: Late Payment Fee Allocation using Late Payment Fee and Payment Transactions from i2C
B11: Installments Revenue (Interest on Installments) | C11: Interests billed on outstanding installment principal including final interest charges upon termination | D11: i2C, Transaction History Settlement Extract
B12: Installments Revenue (Upfront Fee) | C12: One-time set-up fee billed on conversion of purchases into installment | D12: i2C, Transaction History Settlement Extract
B13: Finance Charge (Revolving) | C13: Accrued interests on revolving principal balance | D13: i2C, SSRP_DFC File
... B22: Balance Paymens Volume | C22: Total customer payments received in the last 30 days | D22: i2C, Transaction History Settlement Extract

Sheet Monthly
A1: Monthly KPIs
B2: Forex | C2: 55.8
C4: Ready to ship | D4: Ready to ship | E4: Ready to ship | F4: Ready to ship | G4: Ready to ship | H4: Ready to ship | I4: Ready to ship | J4: Ready to ship | K4: Ready to ship | L4: Ready to ship | M4: Ready to ship | N4: Ready to ship | O4: Ready to ship | P4: Ready to ship | Q4: Ready to ship | R4: Ready to ship | S4: Ready to ship | T4: Ready to ship | U4: Ready to ship | V4: Ready to ship | W4: Ready to ship
C5: 45688 | D5: 45716 | E5: 45747 | F5: 45777 | G5: 45808 | H5: 45838 | I5: 45869 | J5: 45900 | K5: 45930 | L5: 45961 | M5: 45991 | N5: 46022 | O5: 46053 | P5: 46081 | Q5: 46112 | R5: 46142 | S5: 46173 | T5: 46203 | U5: 46234 | V5: 46265 | W5: 46295
B6: CORE METRICS
B7: Monthly Active Users (Revenue) | C7: 400 | D7: 477 | E7: 554 | F7: 705 | G7: 912 | H7: 1354 | I7: 1596 | J7: 1892 | K7: 2391 | L7: 2431 | M7: 2429 | N7: 2672 | O7: 2767 | P7: 3406 | Q7: 4243 | R7: 5339 | S7: 6252 | T7: 7638 | U7: 8555 | V7: 9269 | W7: 11608
B8: Monthly Active Rate | C8: =C7/C23 -> 0.91012514 | D8: =D7/D23 -> 0.82525952 | E8: =E7/E23 -> 0.79597701 | F8: =F7/F23 -> 0.82843713 | G8: =G7/G23 -> 0.80886918 | H8: =H7/H23 -> 0.86324514 | I8: =I7/I23 -> 0.77306854 | J8: =J7/J23 -> 0.70994371 | ... W8: =W7/W23 -> 0.78700973
B10: Monthly Average Revenue Per Active Cardholder / Active User | C10: =C40/C7 -> 577.5386 | D10: =D40/D7 -> 483.81593 | E10: =E40/E7 -> 475.31238 | F10: =F40/F7 -> 442.19067 | G10: =G40/G7 -> 384.11937 | H10: =H40/H7 -> 346.40899 | I10: =I40/I7 -> 361.28972 | J10: =J40/J7 -> 332.19091 | ... W10: =W40/W7 -> 509.39483
B11: Monthly Average Revenue Per Active Cardholder $ / Active User | C11: =C10/$C$2 -> 10.350154 | D11: =D10/$C$2 -> 8.6705364 | E11: =E10/$C$2 -> 8.5181431 | F11: =F10/$C$2 -> 7.9245639 | G11: =G10/$C$2 -> 6.8838598 | H11: =H10/$C$2 -> 6.2080464 | I11: =I10/$C$2 -> 6.4747261 | J11: =J10/$C$2 -> 5.9532421 | ... W11: =W10/$C$2 -> 9.1289396 | X11: =15/X68 -> 0.046012194
B12: MoM Growth | C12: =C10/581.56-1 -> -0.0069148497 | D12: =D10/C10-1 -> -0.16227949 | E12: =E10/D10-1 -> -0.017576003 | F12: =F10/E10-1 -> -0.069684101 | G12: =G10/F10-1 -> -0.13132636 | H12: =H10/G10-1 -> -0.098173613 | I12: =I10/H10-1 -> 0.042957112 | J12: =J10/I10-1 -> -0.080541481 | K12: =K10/J10-1 -> 0.17627139 | ... W12: =W10/V10-1 -> -0.0036018034
B14: Monthly Transacting Users | C14: 398 | D14: 483 | E14: 567 | F14: 715 | G14: 951 | H14: 1369 | I14: 1628 | J14: 1985 | K14: 2380 | L14: 2459 | M14: 2490 | N14: 2699 | O14: 2695 | P14: 3350 | Q14: 4178 | R14: 5252 | S14: 6143 | T14: 7479 | U14: 8387 | V14: 9089 | W14: 11374
B15: MoM Growth | C15: =C14/296-1 -> 0.34459459 | D15: =D14/C14-1 -> 0.21356784 | E15: =E14/D14-1 -> 0.17391304 | F15: =F14/E14-1 -> 0.26102293 | G15: =G14/F14-1 -> 0.33006993 | H15: =H14/G14-1 -> 0.43953733 | I15: =I14/H14-1 -> 0.18918919 | J15: =J14/I14-1 -> 0.21928747 | K15: =K14/J14-1 -> 0.19899244 | ... W15: =W14/V14-1 -> 0.25140279
B16: Monthly Transact Rate | C16: =C14/C23 -> 0.90557452 | D16: =D14/D23 -> 0.83564014 | E16: =E14/E23 -> 0.81465517 | F16: =F14/F23 -> 0.84018801 | G16: =G14/G23 -> 0.84345898 | H16: =H14/H23 -> 0.87280842 | I16: =I14/I23 -> 0.78856866 | J16: =J14/J23 -> 0.74484053 | ... W16: =W14/W23 -> 0.77114478
B17: MoM Growth | C17: =C16/296-1 -> -0.99694063 | D17: =D16/C16-1 -> -0.077226531 | E17: =E16/D16-1 -> -0.025112444 | F17: =F16/E16-1 -> 0.031341901 | G17: =G16/F16-1 -> 0.0038931357 | H17: =H16/G16-1 -> 0.034796518 | I17: =I16/H16-1 -> -0.096515746 | J17: =J16/I16-1 -> -0.05545254 | K17: =K16/J16-1 -> 0.0011953193 | ... W17: =W16/V16-1 -> 0.083836401
B19: SUPPORTING METRICS (Financial/Revenue)
B20: CARDHOLDER ACCOUNTS
B21: Users (end of the month) | C21: 512 | D21: 644 | E21: 748 | F21: 954 | G21: 1301 | H21: 1836 | I21: 2293 | J21: 3037 | K21: 3346 | L21: 3412 | M21: =Daily!LX8 -> 3467 | N21: =Daily!NC8 -> 3831 | O21: =Daily!OH8 -> 4040 | P21: =Daily!PJ8 -> 5113 | Q21: =Daily!QO8 -> 6502 | R21: =Daily!RS8 -> 7561 | S21: =Daily!SX8 -> 9025 | T21: 11366 | U21: =Daily!VH8 -> 12352 | V21: =Daily!WM8 -> 13197 | W21: =Daily!XQ8 -> 16302
B22: MoM Growth | C22: =C21/296-1 -> 0.72972973 | D22: =D21/C21-1 -> 0.2578125 | E22: =E21/D21-1 -> 0.16149068 | F22: =F21/E21-1 -> 0.27540107 | G22: =G21/F21-1 -> 0.36373166 | H22: =H21/G21-1 -> 0.41122214 | I22: =I21/H21-1 -> 0.24891068 | J22: =J21/I21-1 -> 0.32446577 | K22: =K21/J21-1 -> 0.10174514 | ... W22: =W21/V21-1 -> 0.23528075
B23: Users (average) | C23: =AVERAGE(367,C21) -> 439.5 | D23: =AVERAGE(C21,D21) -> 578 | E23: =AVERAGE(D21,E21) -> 696 | F23: =AVERAGE(E21,F21) -> 851 | G23: =AVERAGE(F21,G21) -> 1127.5 | H23: =AVERAGE(G21,H21) -> 1568.5 | I23: =AVERAGE(H21,I21) -> 2064.5 | J23: =AVERAGE(I21,J21) -> 2665 | K23: =AVERAGE(J21,K21) -> 3191.5 | ... W23: =AVERAGE(V21,W21) -> 14749.5
B24: New Users | D24: =D21-C21 -> 132 | E24: =E21-D21 -> 104 | F24: =F21-E21 -> 206 | G24: =G21-F21 -> 347 | H24: =H21-G21 -> 535 | I24: =I21-H21 -> 457 | J24: =J21-I21 -> 744 | K24: =K21-J21 -> 309 | ... W24: =W21-V21 -> 3105
B26: REVENUES | O26: =O27*12 -> 186812.15 | W26: =W27*12 -> 1271624.8
B27: Total Revenue (in USD) | C27: =SUM(C28,C32) -> 4140.0616 | D27: =SUM(D28,D32) -> 4135.8459 | E27: =SUM(E28,E32) -> 4719.0513 | F27: =SUM(F28,F32) -> 5586.8176 | G27: =SUM(G28,G32) -> 6278.0801 | H27: =SUM(H28,H32) -> 8405.6948 | I27: =SUM(I28,I32) -> 10333.663 | J27: =SUM(J28,J32) -> 11263.534 | K27: =SUM(K28,K32) -> 16743.284 | L27: =SUM(L28,L32,L34) -> 17223.997 | M27: =SUM(M28,M32,M34) -> 16778.068 | N27: =SUM(N28,N32,N34) -> 19485.28 | O27: =SUM(O28,O32,O34) -> 15567.679 | P27: =SUM(P28,P32,P34) -> 20247.312 | Q27: =SUM(Q28,Q32,Q34) -> 33956.163 | R27: =SUM(R28,R32,R34) -> 39203.819 | S27: =SUM(S28,S32,S34) -> 40549.077 | T27: =SUM(T28,T32,T34,T38) -> 61149.31 | U27: =SUM(U28,U32,U34,U38) -> 73409.51 | V27: =SUM(V28,V32,V34,V38) -> 84922.014 | W27: =SUM(W28,W32,W34,W38) -> 105968.73 | X27: =W27/O27 -> 6.8069705
B28: Interchange Fee Income | C28: =SUM(C29:C30) -> 4140.0616 | D28: =SUM(D29:D30) -> 4135.8459 | E28: =SUM(E29:E30) -> 4719.0513 | F28: =SUM(F29:F30) -> 5586.8176 | G28: =SUM(G29:G30) -> 6278.0801 | H28: =SUM(H29:H30) -> 8405.6948 | I28: =SUM(I29:I30) -> 10333.663 | J28: =SUM(J29:J30) -> 10940.774 | ... W28: =SUM(W29:W30) -> 47148.563
B29: from PHP settlements | C29: =C43/ForEx -> 2380.5781 | D29: =D43/ForEx -> 2588.7737 | E29: =E43/ForEx -> 2744.3315 | F29: =F43/ForEx -> 3411.8667 | G29: =G43/ForEx -> 3983.1867 | H29: =H43/ForEx -> 5110.1625 | I29: =I43/ForEx -> 6305.7428 | J29: =J43/ForEx -> 6711.6912 | ... W29: =W43/ForEx -> 24756.701
B30: from USD settlements | C30: =C44/ForEx -> 1759.4835 | D30: =D44/ForEx -> 1547.0722 | E30: =E44/ForEx -> 1974.7197 | F30: =F44/ForEx -> 2174.9509 | G30: =G44/ForEx -> 2294.8934 | H30: =H44/ForEx -> 3295.5323 | I30: =I44/ForEx -> 4027.9201 | J30: =J44/ForEx -> 4229.083 | ... W30: =W44/ForEx -> 22391.862
B32: Late Payment Fee | C32: =C49/ForEx -> 0 | D32: =D49/ForEx -> 0 | E32: =E49/ForEx -> 0 | F32: =F49/ForEx -> 0 | G32: =G49/ForEx -> 0 | H32: =H49/ForEx -> 0 | I32: =I49/ForEx -> 0 | J32: =J49/ForEx -> 322.75986 | ... W32: =W49/ForEx -> 2265.7061
X33: =X34/W7 -> 5.686622
B34: Installments Revenue | C34: =SUM(C35:C36) -> 0 | D34: =SUM(D35:D36) -> 0 | E34: =SUM(E35:E36) -> 0 | F34: =SUM(F35:F36) -> 0 | G34: =SUM(G35:G36) -> 0 | H34: =SUM(H35:H36) -> 0 | I34: =SUM(I35:I36) -> 0 | J34: =SUM(J35:J36) -> 0 | ... W34: =SUM(W35:W36) -> 16596.039 | X34: =W34+W32+W28 -> 66010.308
B35: Interest on Installments | O35: =O52/ForEx -> 23.587993 | P35: =P52/ForEx -> 856.01219 | Q35: =Q52/ForEx -> 2401.7299 | R35: =R52/ForEx -> 3943.924 | S35: =S52/ForEx -> 4616.1651 | T35: =T52/ForEx -> 6108.4778 | U35: =U52/ForEx -> 7226.4523 | V35: =V52/ForEx -> 7978.7299 | W35: =W52/ForEx -> 8715.5027
B36: Upfront-fee | O36: =O53/ForEx -> 39.170072 | P36: =P53/ForEx -> 2623.4862 | Q36: =Q53/ForEx -> 5220.6341 | R36: =R53/ForEx -> 5517.1412 | S36: =S53/ForEx -> 5741.8986 | T36: =T53/ForEx -> 6052.8556 | U36: =U53/ForEx -> 5206.3346 | V36: =V53/ForEx -> 6119.3263 | W36: =W53/ForEx -> 7880.5364
X37: =W38/W7 -> 3.4423177
B38: Finance Charge - Revolving | T38: =T55/ForEx -> 12284.291 | U38: =U55/ForEx -> 26911.02 | V38: =V55/ForEx -> 34974.768 | W38: =W55/ForEx -> 39958.423
B40: Total Revenue (in PHP) | C40: =SUM(C42,C49,C51) -> 231015.44 | D40: =SUM(D42,D49,D51) -> 230780.2 | E40: =SUM(E42,E49,E51) -> 263323.06 | F40: =SUM(F42,F49,F51) -> 311744.42 | G40: =SUM(G42,G49,G51) -> 350316.87 | H40: =SUM(H42,H49,H51) -> 469037.77 | I40: =SUM(I42,I49,I51) -> 576618.39 | J40: =SUM(J42,J49,J51) -> 628505.2 | ... S40: =SUM(S42,S49,S51) -> 2262638.5 | T40: =SUM(T42,T49,T51,T55) -> 3412131.5 | U40: =SUM(U42,U49,U51,U55) -> 4096250.6 | V40: =SUM(V42,V49,V51,V55) -> 4738648.4 | W40: =SUM(W42,W49,W51,W55) -> 5913055.2 | X40: =W40/W67 -> 0.028002836 | Y40: =W40/O40 -> 6.8069705
B41: MoM Growth | C41: =C40/296-1 -> 779.45757 | D41: =D40/C40-1 -> -0.0010182869 | E41: =E40/D40-1 -> 0.14101236 | F41: =F40/E40-1 -> 0.18388576 | G41: =G40/F40-1 -> 0.123731 | H41: =H40/G40-1 -> 0.33889575 | I41: =I40/H40-1 -> 0.22936451 | J41: =J40/I40-1 -> 0.08998466 | K41: =K40/J40-1 -> 0.48650364 | ... W41: =W40/V40-1 -> 0.24783583
B42: Interchange Fee Revenue | C42: =SUM(C43:C44) -> 231015.44 | D42: =SUM(D43:D44) -> 230780.2 | E42: =SUM(E43:E44) -> 263323.06 | F42: =SUM(F43:F44) -> 311744.42 | G42: =SUM(G43:G44) -> 350316.87 | H42: =SUM(H43:H44) -> 469037.77 | I42: =SUM(I43:I44) -> 576618.39 | J42: =SUM(J43:J44) -> 610495.2 | ... W42: =SUM(W43:W44) -> 2630889.8 | X42: =W42/$W$40 -> 0.44492901 | Y42: =W42/W67 -> 0.012459274
B43: from PHP settlements | C43: 132836.26 | D43: 144453.57 | E43: 153133.7 | F43: 190382.16 | G43: 222261.82 | H43: 285147.07 | I43: 351860.45 | J43: 374512.37 | K43: 524935.95 | L43: 511370.68 | M43: 524190.36 | N43: =570005.93+45165.27 -> 615171.2 | O43: =473195.71-45165.27 -> 428030.44 | P43: 470518.06 | Q43: 713547.5 | R43: 745657.84 | S43: 861989.74 | T43: 1005284.9 | U43: 850608.48 | V43: 860091.33 | W43: 1381423.9
B44: from USD settlements | C44: 98179.18 | D44: 86326.63 | E44: 110189.36 | F44: 121362.26 | G44: 128055.05 | H44: 183890.7 | I44: 224757.94 | J44: 235982.83 | K44: 353418.65 | L44: 395728.36 | M44: 367025.81 | N44: 440107.44 | O44: 372436.52 | P44: 394114.87 | Q44: 651073.19 | R44: 775875.43 | S44: 683618.88 | T44: 957909.19 | U44: 960836.27 | V44: 1032118.8 | W44: 1249465.9
B46: from USD settlements | C46: 1671.15 | D46: 1483.93 | E46: 1917.09 | F46: 2126.46 | G46: 2297.8 | H46: 3261.93 | I46: 3954.72 | J46: 4120.67 | K46: 6171.23 | L46: 6784.49 | M46: 6224.82 | N46: 7472.84 | O46: 6294.13 | P46: 6657.78 | Q46: 10960.97 | R46: 12872.83 | S46: 11128.97 | T46: 15636.11 | U46: 15596.98 | V46: 16792.13 | W46: 19940.25
B47: Forex (Revenue) | C47: =C44/C46 -> 58.749472 | D47: =D44/D46 -> 58.174328 | E47: =E44/E46 -> 57.477406 | F47: =F44/F46 -> 57.07244 | G47: =G44/G46 -> 55.729415 | H47: =H44/H46 -> 56.374815 | I47: =I44/I46 -> 56.832833 | J47: =J44/J46 -> 57.268073 | ... T47: =T44/T46 -> 61.262628 | V47: =V44/V46 -> 61.464436 | W47: =W44/W46 -> 62.660493
B49: Late Payment Fee Revenue | C49: 0 | D49: 0 | E49: 0 | F49: 0 | G49: 0 | H49: 0 | I49: 0 | J49: 18010 | K49: 55920.67 | L49: 54000 | M49: 45000 | N49: 32000 | O49: 64707.62 | P49: 71011.07 | Q49: 104805.31 | R49: 138112.4 | S49: 139049.93 | T49: 84871.59 | U49: 89421.49 | V49: 108174.67 | W49: 126426.4
...

Sheet Daily
A1: Daily KPIs | WE1: =WE8-VY8 -> 107 | WF1: 380 | WG1: 720 | WH1: =WI2-WH2 -> -1001.7 | WI1: =WI2-WF8 -> 286 | WT1: =WT8*1.1 -> 16677.1
UV2: =UV8-UC8 -> 214 | WG2: =WH2-WF8 -> 1287.7 | WH2: =1.1*WF8 -> 14164.7 | WI2: 13163 | WT2: =WT1-WT8 -> 1516.1
B3: Forex | C3: 55.8 | SJ3: 60 | SK3: 60 | SL3: 60 | SM3: 60 | SN3: 60 | SO3: 60 | SP3: 60 | SQ3: 60 | SR3: 60 | SS3: 60 | ST3: 60 | SU3: 60 | SV3: 60 | SW3: 60 | SX3: 60 | SY3: 55.8 | SZ3: 55.8 | TA3: 55.8 | TB3: 55.8 | TC3: 55.8 | TD3: 55.8 | TE3: 55.8 | TF3: 55.8 | TG3: 55.8 | TH3: 55.8 | TI3: 55.8 | TJ3: 55.8 | TK3: 55.8 | TL3: 55.8 | TM3: 55.8 | TN3: 55.8 | TO3: 55.8 | TP3: 55.8 | TQ3: 55.8 | TR3: 55.8 | TS3: 55.8 | TT3: 55.8 | TU3: 55.8 | TV3: 55.8 | TW3: 55.8 | TX3: 55.8 | TY3: 55.8 | TZ3: 55.8 | UA3: 55.8 | UB3: 55.8 | UC3: 55.8 | UD3: 55.8 | UE3: 55.8 | UF3: 55.8 | UG3: 55.8 | UH3: 55.8 | UI3: 55.8 | UJ3: 55.8 | UK3: 55.8 | UL3: 55.8 | UM3: 55.8 | UN3: 55.8 | UO3: 55.8 | UP3: 55.8 | UQ3: 55.8 | UR3: 55.8 | US3: 55.8 | UT3: 55.8 | UU3: 55.8 | UV3: 55.8 | UW3: 55.8 | UX3: 55.8 | UY3: 55.8 | UZ3: 55.8 | VA3: 55.8 | VB3: 55.8 | VC3: 55.8 | VD3: 55.8 | VE3: 55.8 | VF3: 55.8 | VG3: 55.8 | VH3: 55.8 | VI3: 55.8 | VJ3: 55.8 | VK3: 55.8 | VL3: 55.8 | VM3: 55.8 | VN3: 55.8 | VO3: 55.8 | VP3: 55.8 | VQ3: 55.8 | VR3: 55.8 | VS3: 55.8 | VT3: 55.8 | VU3: 55.8 | VV3: 55.8 | VW3: 55.8 | VX3: 55.8 | VY3: 55.8 | VZ3: 55.8 | WA3: 55.8 | WB3: 55.8 | WC3: 55.8 | WD3: 55.8 | WE3: 55.8 | WF3: 55.8 | WG3: 55.8 | WH3: 55.8 | WI3: 55.8 | WJ3: 55.8 | WK3: 55.8 | WL3: 55.8 | WM3: 55.8 | WN3: 55.8 | WO3: 55.8 | WP3: 55.8 | WQ3: 55.8 | WR3: 55.8 | WS3: 55.8 | WT3: 55.8 | WU3: 55.8 | WV3: 55.8 | WW3: 55.8 | WX3: 55.8 | WY3: 55.8 | WZ3: 55.8 | XA3: 55.8 | XB3: 55.8 | XC3: 55.8 | XD3: 55.8 | XE3: 55.8 | XF3: 55.8 | XG3: 55.8 | XH3: 55.8 | XI3: 55.8 | XJ3: 55.8 | XK3: 55.8 | XL3: 55.8 | XM3: 55.8 | XN3: 55.8 | XO3: 55.8 | XP3: 55.8 | XQ3: 55.8 | XR3: 55.8 | XS3: 55.8 | XT3: 55.8 | XU3: 55.8 | XV3: 55.8 | XW3: 55.8 | XX3: 55.8 | XY3: 55.8 | XZ3: 55.8 | YA3: 55.8 | YB3: 55.8 | YC3: 55.8 | YD3: 55.8 | YE3: 55.8 | YF3: 55.8 | YG3: 55.8 | YH3: 55.8 | YI3: 55.8 | YJ3: 55.8 | YK3: 55.8 | YL3: 55.8 | YM3: 55.8
WI4: =WI8-NC8 -> 9249
C5: 45658 | D5: 45659 | E5: 45660 | F5: 45661 | G5: 45662 | H5: 45663 | I5: 45664 | J5: 45665 | K5: 45666 | L5: 45667 | M5: 45668 | N5: 45669 | O5: 45670 | P5: 45671 | Q5: 45672 | R5: 45673 | S5: 45674 | T5: 45675 | U5: 45676 | V5: 45677 | W5: 45678 | X5: 45679 | Y5: 45680 | Z5: 45681 | AA5: 45682 | AB5: 45683 | AC5: 45684 | AD5: 45685 | AE5: 45686 | AF5: 45687 | AG5: 45688 | AH5: 45689 | AI5: 45690 | AJ5: 45691 | AK5: 45692 | AL5: 45693 | AM5: 45694 | AN5: 45695 | AO5: 45696 | AP5: 45697 | AQ5: 45698 | AR5: 45699 | AS5: 45700 | AT5: 45701 | AU5: 45702 | AV5: 45703 | AW5: 45704 | AX5: 45705 | AY5: 45706 | AZ5: 45707 | BA5: 45708 | BB5: 45709 | BC5: 45710 | BD5: 45711 | BE5: 45712 | BF5: 45713 | BG5: 45714 | BH5: 45715 | BI5: 45716 | BJ5: 45717 | BK5: 45718 | BL5: 45719 | BM5: 45720 | BN5: 45721 | BO5: 45722 | BP5: 45723 | BQ5: 45724 | BR5: 45725 | BS5: 45726 | BT5: 45727 | BU5: 45728 | BV5: 45729 | BW5: 45730 | BX5: 45731 | BY5: 45732 | BZ5: 45733 | CA5: 45734 | CB5: 45735 | CC5: 45736 | CD5: 45737 | CE5: 45738 | CF5: 45739 | CG5: 45740 | CH5: 45741 | CI5: 45742 | CJ5: 45743 | CK5: 45744 | CL5: 45745 | CM5: 45746 | CN5: 45747 | CO5: 45748 | CP5: 45749 | CQ5: 45750 | CR5: 45751 | CS5: 45752 | CT5: 45753 | CU5: 45754 | CV5: 45755 | CW5: 45756 | CX5: 45757 | CY5: 45758 | CZ5: 45759 | DA5: 45760 | DB5: 45761 | DC5: 45762 | DD5: 45763 | DE5: 45764 | DF5: 45765 | DG5: 45766 | DH5: 45767 | DI5: 45768 | DJ5: 45769 | DK5: 45770 | DL5: 45771 | DM5: 45772 | DN5: 45773 | DO5: 45774 | DP5: 45775 | DQ5: 45776 | DR5: 45777 | DS5: 45778 | DT5: 45779 | DU5: 45780 | DV5: 45781 | DW5: 45782 | DX5: 45783 | DY5: 45784 | DZ5: 45785 | EA5: 45786 | EB5: 45787 | EC5: 45788 | ED5: 45789 | EE5: 45790 | EF5: 45791 | EG5: 45792 | EH5: 45793 | EI5: 45794 | EJ5: 45795 | EK5: 45796 | EL5: 45797 | EM5: 45798 | EN5: 45799 | EO5: 45800 | EP5: 45801 | EQ5: 45802 | ER5: 45803 | ES5: 45804 | ET5: 45805 | EU5: 45806 | EV5: 45807 | EW5: 45808 | EX5: 45809 | EY5: 45810 | EZ5: 45811 | FA5: 45812 | FB5: 45813 | FC5: 45814 | FD5: 45815 | FE5: 45816 | FF5: 45817 | FG5: 45818 | FH5: 45819 | FI5: 45820 | FJ5: 45821 | FK5: 45822 | FL5: 45823 | FM5: 45824 | FN5: 45825 | FO5: 45826 | FP5: 45827 | FQ5: 45828 | FR5: 45829 | FS5: 45830 | FT5: 45831 | FU5: 45832 | FV5: 45833 | FW5: 45834 | FX5: 45835 | FY5: 45836 | FZ5: 45837 | GA5: 45838 | GB5: 45839 | GC5: 45840 | GD5: 45841 | GE5: 45842 | GF5: 45843 | GG5: 45844 | GH5: 45845 | GI5: 45846 | GJ5: 45847 | GK5: 45848 | GL5: 45849 | GM5: 45850 | GN5: 45851 | GO5: 45852 | GP5: 45853 | GQ5: 45854 | GR5: 45855 | GS5: 45856 | GT5: 45857 | GU5: 45858 | GV5: 45859 | GW5: 45860 | GX5: 45861 | GY5: 45862 | GZ5: 45863 | HA5: 45864 | HB5: 45865 | HC5: 45866 | HD5: 45867 | HE5: 45868 | HF5: 45869 | HG5: 45870 | HH5: 45871 | HI5: 45872 | HJ5: 45873 | HK5: 45874 | HL5: 45875 | HM5: 45876 | HN5: 45877 | HO5: 45878 | HP5: 45879 | HQ5: 45880 | HR5: 45881 | HS5: 45882 | HT5: 45883 | HU5: 45884 | HV5: 45885 | HW5: 45886 | HX5: 45887 | HY5: 45888 | HZ5: 45889 | IA5: 45890 | IB5: 45891 | IC5: 45892 | ID5: 45893 | IE5: 45894 | IF5: 45895 | IG5: 45896 | IH5: 45897 | II5: 45898 | IJ5: 45899 | IK5: 45900 | IL5: 45901 | IM5: 45902 | IN5: 45903 | IO5: 45904 | IP5: 45905 | IQ5: 45906 | IR5: 45907 | IS5: 45908 | IT5: 45909 | IU5: 45910 | IV5: 45911 | IW5: 45912 | IX5: 45913 | IY5: 45914 | IZ5: 45915 | JA5: 45916 | JB5: 45917 | JC5: 45918 | JD5: 45919 | JE5: 45920 | JF5: 45921 | JG5: 45922 | JH5: 45923 | JI5: 45924 | JJ5: 45925 | JK5: 45926 | JL5: 45927 | JM5: 45928 | JN5: 45929 | JO5: 45930 | JP5: 45931 | JQ5: 45932 | JR5: 45933 | JS5: 45934 | JT5: 45935 | JU5: 45936 | JV5: 45937 | JW5: 45938 | JX5: 45939 | JY5: 45940 | JZ5: 45941 | KA5: 45942 | KB5: 45943 | KC5: 45944 | KD5: 45945 | KE5: 45946 | KF5: 45947 | KG5: 45948 | KH5: 45949 | KI5: 45950 | KJ5: 45951 | KK5: 45952 | KL5: 45953 | KM5: 45954 | KN5: 45955 | KO5: 45956 | KP5: 45957 | KQ5: 45958 | KR5: 45959 | KS5: 45960 | KT5: 45961 | KU5: 45962 | KV5: 45963 | KW5: 45964 | KX5: 45965 | KY5: 45966 | KZ5: 45967 | LA5: 45968 | LB5: 45969 | LC5: 45970 | LD5: 45971 | LE5: 45972 | LF5: 45973 | LG5: 45974 | LH5: 45975 | LI5: 45976 | LJ5: 45977 | LK5: 45978 | LL5: 45979 | LM5: 45980 | LN5: 45981 | LO5: 45982 | LP5: 45983 | LQ5: 45984 | LR5: 45985 | LS5: 45986 | LT5: 45987 | LU5: 45988 | LV5: 45989 | LW5: 45990 | LX5: 45991 | LY5: 45992 | LZ5: 45993 | MA5: 45994 | MB5: 45995 | MC5: 45996 | MD5: 45997 | ME5: 45998 | MF5: 45999 | MG5: 46000 | MH5: 46001 | MI5: 46002 | MJ5: 46003 | MK5: 46004 | ML5: 46005 | MM5: 46006 | MN5: 46007 | MO5: 46008 | MP5: 46009 | MQ5: 46010 | MR5: 46011 | MS5: 46012 | MT5: 46013 | MU5: 46014 | MV5: 46015 | MW5: 46016 | MX5: 46017 | MY5: 46018 | MZ5: 46019 | NA5: 46020 | NB5: 46021 | NC5: 46022 | ND5: 46023 | NE5: 46024 | NF5: 46025 | NG5: 46026 | NH5: 46027 | NI5: 46028 | NJ5: 46029 | NK5: 46030 | NL5: 46031 | NM5: 46032 | NN5: 46033 | NO5: 46034 | NP5: 46035 | NQ5: 46036 | NR5: 46037 | NS5: 46038 | NT5: 46039 | NU5: 46040 | NV5: 46041 | NW5: 46042 | NX5: 46043 | NY5: 46044 | NZ5: 46045 | OA5: 46046 | OB5: 46047 | OC5: 46048 | OD5: 46049 | OE5: 46050 | OF5: 46051 | OG5: 46052 | OH5: 46053 | OI5: 46054 | OJ5: 46055 | OK5: 46056 | OL5: 46057 | OM5: 46058 | ON5: 46059 | OO5: 46060 | OP5: 46061 | OQ5: 46062 | OR5: 46063 | OS5: 46064 | OT5: 46065 | OU5: 46066 | OV5: 46067 | OW5: 46068 | OX5: 46069 | OY5: 46070 | OZ5: 46071 | PA5: 46072 | PB5: 46073 | PC5: 46074 | PD5: 46075 | PE5: 46076 | PF5: 46077 | PG5: 46078 | PH5: 46079 | PI5: 46080 | PJ5: 46081 | PK5: 46082 | PL5: 46083 | PM5: 46084 | PN5: 46085 | PO5: 46086 | PP5: 46087 | PQ5: 46088 | PR5: 46089 | PS5: 46090 | PT5: 46091 | PU5: 46092 | PV5: 46093 | PW5: 46094 | PX5: 46095 | PY5: 46096 | PZ5: 46097 | QA5: 46098 | QB5: 46099 | QC5: 46100 | QD5: 46101 | QE5: 46102 | QF5: 46103 | QG5: 46104 | QH5: 46105 | QI5: 46106 | QJ5: 46107 | QK5: 46108 | QL5: 46109 | QM5: 46110 | QN5: 46111 | QO5: 46112 | QP5: 46113 | QQ5: 46114 | QR5: 46115 | QS5: 46116 | QT5: 46117 | QU5: 46118 | QV5: 46119 | QW5: 46120 | QX5: 46121 | QY5: 46122 | QZ5: 46123 | RA5: 46124 | RB5: 46125 | RC5: 46126 | RD5: 46127 | RE5: 46128 | RF5: 46129 | RG5: 46130 | RH5: 46131 | RI5: 46132 | RJ5: 46133 | RK5: 46134 | RL5: 46135 | RM5: 46136 | RN5: 46137 | RO5: 46138 | RP5: 46139 | RQ5: 46140 | RR5: 46141 | RS5: 46142 | RT5: 46143 | RU5: 46144 | RV5: 46145 | RW5: 46146 | RX5: 46147 | RY5: 46148 | RZ5: 46149 | SA5: 46150 | SB5: 46151 | SC5: 46152 | SD5: 46153 | SE5: 46154 | SF5: 46155 | SG5: 46156 | SH5: 46157 | SI5: 46158 | SJ5: 46159 | SK5: 46160 | SL5: 46161 | SM5: 46162 | SN5: 46163 | SO5: 46164 | SP5: 46165 | SQ5: 46166 | SR5: 46167 | SS5: 46168 | ST5: 46169 | SU5: 46170 | SV5: 46171 | SW5: 46172 | SX5: 46173 | SY5: 46174 | SZ5: 46175 | TA5: 46176 | TB5: 46177 | TC5: 46178 | TD5: 46179 | TE5: 46180 | TF5: 46181 | TG5: 46182 | TH5: 46183 | TI5: 46184 | TJ5: 46185 | TK5: 46186 | TL5: 46187 | TM5: 46188 | TN5: 46189 | TO5: 46190 | TP5: 46191 | TQ5: 46192 | TR5: 46193 | TS5: 46194 | TT5: 46195 | TU5: 46196 | TV5: 46197 | TW5: 46198 | TX5: 46199 | TY5: 46200 | TZ5: 46201 | UA5: 46202 | UB5: 46203 | UC5: 46204 | UD5: 46205 | UE5: 46206 | UF5: 46207 | UG5: 46208 | UH5: 46209 | UI5: 46210 | UJ5: 46211 | UK5: 46212 | UL5: 46213 | UM5: 46214 | UN5: 46215 | UO5: 46216 | UP5: 46217 | UQ5: 46218 | UR5: 46219 | US5: 46220 | UT5: 46221 | UU5: 46222 | UV5: 46223 | UW5: 46224 | UX5: 46225 | UY5: 46226 | UZ5: 46227 | VA5: 46228 | VB5: 46229 | VC5: 46230 | VD5: 46231 | VE5: 46232 | VF5: 46232 | VG5: 46233 | VH5: 46234 | VI5: 46235 | VJ5: 46236 | VK5: 46237 | VL5: 46238 | VM5: 46239 | VN5: 46240 | VO5: 46241 | VP5: 46242 | VQ5: 46243 | VR5: 46244 | VS5: 46245 | VT5: 46246 | VU5: 46247 | VV5: 46248 | VW5: 46249 | VX5: 46250 | VY5: 46251 | VZ5: 46252 | WA5: 46253 | WB5: 46254 | WC5: 46255 | WD5: 46256 | WE5: 46257 | WF5: 46258 | WG5: 46259 | WH5: 46260 | WI5: 46261 | WJ5: 46262 | WK5: 46263 | WL5: 46264 | WM5: 46265 | WN5: 46266 | WO5: 46267 | WP5: 46268 | WQ5: 46269 | WR5: 46270 | WS5: 46271 | WT5: 46272 | WU5: 46273 | WV5: 46274 | WW5: 46275 | WX5: 46276 | WY5: 46277 | WZ5: 46278 | XA5: 46279 | XB5: 46280 | XC5: 46281 | XD5: 46282 | XE5: 46283 | XF5: 46284 | XG5: 46285 | XH5: 46286 | XI5: 46287 | XJ5: 46288 | XK5: 46289 | XL5: 46290 | XM5: 46291 | XN5: 46292 | XO5: 46293 | XP5: 46294 | XQ5: 46295 | XR5: 46296 | XS5: 46297 | XT5: 46298 | XU5: 46299 | XV5: 46300 | XW5: 46301 | XX5: 46302 | XY5: 46303 | XZ5: 46304 | YA5: 46305 | YB5: 46306 | YC5: 46307 | YD5: 46308 | YE5: 46309 | YF5: 46310 | YG5: 46311 | YH5: 46312 | YI5: 46313 | YJ5: 46314 | YK5: 46315 | YL5: 46316 | YM5: 46317
B6: CORE METRICS
B7: Cardholder Accounts | VC7: =VC8-UC8 -> 643
B8: Users | C8: 367 | D8: 367 | E8: 373 | F8: 376 | G8: 376 | H8: 376 | I8: 386 | J8: 396 | K8: 405 | L8: 416 | M8: 415 | N8: 415 | O8: 415 | P8: 421 | Q8: 432 | R8: 440 | S8: 448 | T8: 450 | U8: 450 | V8: 451 | W8: 462 | X8: 475 | Y8: 487 | Z8: 503 | AA8: 503 | AB8: 503 | AC8: 503 | AD8: 503 | AE8: 504 | AF8: 505 | AG8: 512 | AH8: 512 | AI8: 512 | AJ8: 512 | AK8: 523 | AL8: 533 | AM8: 536 | AN8: 542 | AO8: 544 | AP8: 544 | AQ8: 544 | AR8: 554 | AS8: 569 | AT8: 571 | AU8: 577 | AV8: 577 | AW8: 577 | AX8: 581 | AY8: 582 | AZ8: 599 | BA8: 602 | BB8: 609 | BC8: 609 | BD8: 609 | BE8: 611 | BF8: 624 | BG8: 632 | BH8: 643 | BI8: 644 | BJ8: 644 | BK8: 644 | BL8: 644 | BM8: 644 | BN8: 644 | BO8: 644 | BP8: 645 | BQ8: 645 | BR8: 655 | BS8: 655 | BT8: 661 | BU8: 661 | BV8: 663 | BW8: 669 | BX8: 669 | BY8: 669 | BZ8: 669 | CA8: 682 | CB8: 692 | CC8: 698 | CD8: 703 | CE8: 703 | CF8: 703 | CG8: 708 | CH8: 709 | CI8: 719 | CJ8: 737 | CK8: 737 | CL8: 737 | CM8: 737 | CN8: 748 | CO8: 748 | CP8: 765 | CQ8: 775 | CR8: 778 | CS8: 778 | CT8: 778 | CU8: 799 | CV8: 792 | CW8: 801 | CX8: 804 | CY8: 804 | CZ8: 804 | DA8: 804 | DB8: 808 | DC8: 809 | DD8: 842 | DE8: 861 | DF8: 878 | DG8: 878 | DH8: 878 | DI8: 886 | DJ8: 886 | DK8: 905 | DL8: 913 | DM8: 913 | DN8: 913 | DO8: 913 | DP8: 931 | DQ8: 943 | DR8: 954 | DS8: 954 | DT8: 955 | DU8: 955 | DV8: 955 | DW8: 955 | DX8: 969 | DY8: 982 | DZ8: 1000 | EA8: 1000 | EB8: 1000 | EC8: 1000 | ED8: 1000 | EE8: 1000 | EF8: 1000 | EG8: 1026 | EH8: 1041 | EI8: 1041 | EJ8: 1056 | EK8: 1100 | EL8: 1170 | EM8: 1185 | EN8: 1200 | EO8: 1208 | EP8: 1208 | EQ8: 1208 | ER8: 1208 | ES8: 1252 | ET8: 1274 | EU8: 1289 | EV8: 1301 | EW8: 1301 | EX8: 1301 | EY8: 1321 | EZ8: 1352 | FA8: 1406 | FB8: 1425 | FC8: 1432 | FD8: 1432 | FE8: 1432 | FF8: 1432 | FG8: 1502 | FH8: 1517 | FI8: 1517 | FJ8: 1602 | FK8: 1602 | FL8: 1602 | FM8: 1646 | FN8: 1669 | FO8: 1738 | FP8: 1759 | FQ8: 1759 | FR8: 1760 | FS8: 1760 | FT8: 1804 | FU8: 1836 | FV8: 1836 | FW8: 1836 | FX8: 1836 | FY8: 1836 | FZ8: 1836 | GA8: 1836 | GB8: 1836 | GC8: 1836 | GD8: 1836 | GE8: 1836 | GF8: 1836 | GG8: 1836 | GH8: 1858 | GI8: 1858 | GJ8: 1877 | GK8: 1917 | GL8: 2003 | GM8: 2003 | GN8: 2003 | GO8: 2052 | GP8: 2052 | GQ8: 2052 | GR8: 2052 | GS8: 2068 | GT8: 2068 | GU8: 2135 | GV8: 2165 | GW8: 2165 | GX8: 2165 | GY8: 2165 | GZ8: 2219 | HA8: 2219 | HB8: 2219 | HC8: 2261 | HD8: 2261 | HE8: 2276 | HF8: 2293 | HG8: 2304 | HH8: 2304 | HI8: 2304 | HJ8: 2304 | HK8: 2324 | HL8: 2327 | HM8: 2342 | HN8: 2350 | HO8: 2350 | HP8: 2350 | HQ8: 2371 | HR8: 2372 | HS8: 2377 | HT8: 2382 | HU8: 2425 | HV8: 2425 | HW8: 2425 | HX8: 2651 | HY8: 2651 | HZ8: 2651 | IA8: 2651 | IB8: 2651 | IC8: 2651 | ID8: 2651 | IE8: 2651 | IF8: 2651 | IG8: 2857 | IH8: 2858 | II8: 2858 | IJ8: 2858 | IK8: 3037 | IL8: 3037 | IM8: 3039 | IN8: 3041 | IO8: 3041 | IP8: 3175 | IQ8: 3182 | IR8: 3182 | IS8: 3215 | IT8: 3215 | IU8: 3217 | IV8: 3262 | IW8: 3266 | IX8: 3266 | IY8: 3266 | IZ8: 3268 | JA8: 3275 | JB8: 3279 | JC8: 3279 | JD8: 3279 | JE8: 3279 | JF8: 3279 | JG8: 3279 | JH8: 3279 | JI8: 3281 | JJ8: 3313 | JK8: 3313 | JL8: 3313 | JM8: 3313 | JN8: 3335 | JO8: 3336 | JP8: 3346 | JQ8: 3346 | JR8: 3345 | JS8: 3345 | JT8: 3345 | JU8: 3345 | JV8: 3350 | JW8: 3350 | JX8: 3350 | JY8: 3365 | JZ8: 3365 | KA8: 3365 | KB8: 3365 | KC8: 3365 | KD8: 3365 | KE8: 3370 | KF8: 3370 | KG8: 3370 | KH8: 3370 | KI8: 3381 | KJ8: 3381 | KK8: 3403 | KL8: 3413 | KM8: 3413 | KN8: 3413 | KO8: 3413 | KP8: 3413 | KQ8: 3413 | KR8: 3412 | KS8: 3412 | KT8: 3412 | KU8: 3412 | KV8: 3412 | KW8: 3423 | KX8: 3423 | KY8: 3423 | KZ8: 3423 | LA8: 3423 | LB8: 3423 | LC8: 3423 | LD8: 3423 | LE8: 3472 | LF8: 3471 | LG8: 3474 | LH8: 3474 | LI8: 3474 | LJ8: 3474 | LK8: 3474 | LL8: 3474 | LM8: 3465 | LN8: 3465 | LO8: 3465 | LP8: 3465 | LQ8: 3465 | LR8: 3465 | LS8: 3467 | LT8: 3467 | LU8: 3467 | LV8: 3467 | LW8: 3467 | LX8: 3467 | LY8: 3467 | LZ8: 3467 | MA8: 3452 | MB8: 3452 | MC8: 3707 | MD8: 3707 | ME8: 3707 | MF8: 3707 | MG8: 3707 | MH8: 3707 | MI8: 3766 | MJ8: 3757 | MK8: 3757 | ML8: 3757 | MM8: 3792 | MN8: 3792 | MO8: 3829 | MP8: 3831 | MQ8: 3831 | MR8: 3831 | MS8: 3831 | MT8: 3831 | MU8: 3831 | MV8: 3831 | MW8: 3831 | MX8: 3831 | MY8: 3831 | MZ8: 3831 | NA8: 3831 | NB8: 3831 | NC8: 3831 | ND8: 3831 | NE8: 3831 | NF8: 3831 | NG8: 3831 | NH8: 3828 | NI8: 3823 | NJ8: 3839 | NK8: 3839 | NL8: 3839 | NM8: 3839 | NN8: 3839 | NO8: 3861 | NP8: 3862 | NQ8: 3862 | NR8: 3862 | NS8: 3861 | NT8: 3861 | NU8: 3861 | NV8: 3875 | NW8: 3875 | NX8: 3875 | NY8: 3875 | NZ8: 3875 | OA8: 3875 | OB8: 3875 | OC8: 3875 | OD8: 3913 | OE8: 3965 | OF8: 4000 | OG8: 4040 | OH8: 4040 | OI8: 4040 | OJ8: 4061 | OK8: 4083 | OL8: 4083 | OM8: 4091 | ON8: 4103 | OO8: 4103 | OP8: 4103 | OQ8: 4103 | OR8: 4153 | OS8: 4232 | OT8: 4272 | OU8: 4306 | OV8: 4306 | OW8: 4385 | OX8: 4434 | OY8: 4477 | OZ8: 4593 | PA8: 4708 | PB8: 4720 | PC8: 4796 | PD8: 4796 | PE8: 4810 | PF8: 4852 | PG8: 4986 | PH8: 5082 | PI8: 5113 | PJ8: 5113 | PK8: 5113 | PL8: 5145 | PM8: 5177 | PN8: 5180 | PO8: 5180 | PP8: 5202 | PQ8: 5202 | PR8: 5202 | PS8: 5200 | PT8: 5257 | PU8: 5268 | PV8: 5292 | PW8: 5392 | PX8: 5392 | PY8: 5392 | PZ8: 5438 | QA8: 5437 | QB8: 5569 | QC8: 5569 | QD8: 5649 | QE8: 5649 | QF8: 5694 | QG8: 5694 | QH8: 5694 | QI8: 5694 | QJ8: 5876 | QK8: 5965 | QL8: 5965 | QM8: 5965 | QN8: 6005 | QO8: 6502 | QP8: 6498 | QQ8: 6498 | QR8: 6849 | QS8: 6849 | QT8: 6849 | QU8: 6847 | QV8: 7045 | QW8: 7084 | QX8: 7084 | QY8: 7084 | QZ8: 7084 | RA8: 7084 | RB8: 7081 | RC8: 7174 | RD8: 7174 | RE8: 7231 | RF8: 7231 | RG8: 7231 | RH8: 7231 | RI8: 7300 | RJ8: 7356 | RK8: 7356 | RL8: 7357 | RM8: 7506 | RN8: 7506 | RO8: 7506 | RP8: 7566 | RQ8: 7566 | RR8: 7562 | RS8: 7561 | RT8: 7561 | RU8: 7561 | RV8: 7561 | RW8: 7561 | RX8: 7728 | RY8: 7870 | RZ8: 7920 | SA8: 7920 | SB8: 7920 | SC8: 7920 | SD8: 8126 | SE8: 8126 | SF8: 8153 | SG8: 8232 | SH8: 8232 | SI8: 8233 | SJ8: 8233 | SK8: 8366 | SL8: 8538 | SM8: 8571 | SN8: 8571 | SO8: 8638 | SP8: 8638 | SQ8: 8638 | SR8: 8638 | SS8: 8772 | ST8: 8908 | SU8: 8981 | SV8: 9025 | SW8: 9025 | SX8: 9025 | SY8: 9024 | SZ8: 9024 | TA8: 9092 | TB8: 9091 | TC8: 9253 | TD8: 9253 | TE8: 9253 | TF8: 9292 | TG8: 9656 | TH8: 9786 | TI8: 9784 | TJ8: 9784 | TK8: 9784 | TL8: 9784 | TM8: 9984 | TN8: 10265 | TO8: 10421 | TP8: 10449 | TQ8: 10449 | TR8: 10449 | TS8: 10449 | TT8: 10449 | TU8: 10879 | TV8: 10926 | TW8: 10942 | TX8: 11075 | TY8: 11075 | TZ8: 11075 | UA8: 11086 | UB8: 11382 | UC8: 11394 | UD8: 11394 | UE8: 11388 | UF8: 11388 | UG8: 11388 | UH8: 11388 | UI8: 11385 | UJ8: 11503 | UK8: 11517 | UL8: 11517 | UM8: 11517 | UN8: 11517 | UO8: 11540 | UP8: 11540 | UQ8: 11584 | UR8: 11596 | US8: 11608 | UT8: 11608 | UU8: 11608 | UV8: 11608 | UW8: 11911 | UX8: 11941 | UY8: 12025 | UZ8: 12025 | VA8: 12025 | VB8: 12025 | VC8: 12037 | VD8: 12041 | VE8: 12155 | VF8: 12155 | VG8: 12295 | VH8: 12352 | VI8: 12353 | VJ8: 12353 | VK8: 12352 | VL8: 12352 | VM8: 12448 | VN8: 12448 | VO8: 12565 | VP8: 12565 | VQ8: 12565 | VR8: 12598 | VS8: 12733 | VT8: 12733 | VU8: 12733 | VV8: 12770 | VW8: 12770 | VX8: 12770 | VY8: 12770 | VZ8: 12770 | WA8: 12877 | WB8: 12877 | WC8: 12877 | WD8: 12877 | WE8: 12877 | WF8: 12877 | WG8: 13069 | WH8: 13069 | WI8: 13080 | WJ8: 13197 | WK8: 13197 | WL8: 13197 | WM8: 13197 | WN8: 14031 | WO8: 14268 | WP8: 14308 | WQ8: 14308 | WR8: 14892 | WS8: 14962 | WT8: 15161 | WU8: 15160 | WV8: 15160 | WW8: 15348 | WX8: 15392 | WY8: 15392 | WZ8: 15392 | XA8: 15392 | XB8: 15563 | XC8: 15661 | XD8: 15675 | XE8: 15731 | XF8: 15731 | XG8: 15731 | XH8: 15777 | XI8: 15811 | XJ8: 15877 | XK8: 15959 | XL8: 16034 | XM8: 16034 | XN8: 16034 | XO8: 16034 | XP8: 16303 | XQ8: 16302 | XR8: 16302 | XS8: 16302 | XT8: 16302 | XU8: 16302 | XV8: 16302 | XW8: 16303 | XX8: 16303 | XY8: 16303 | XZ8: 16302 | YA8: 16302 | YB8: 16302 | YC8: 16302 | YD8: 16302 | YE8: 16302 | YF8: 16302 | YG8: 16302 | YH8: 16302 | YI8: 16302 | YJ8: 16301 | YK8: 16301 | YL8: 16301 | YM8: 16301
B9: New Users (Closures) | AG9: =AG8-AF8 -> 7 | AH9: =AH8-AG8 -> 0 | AI9: =AI8-AH8 -> 0 | AJ9: =AJ8-AI8 -> 0 | AK9: =AK8-AJ8 -> 11 | AL9: =AL8-AK8 -> 10 | AM9: =AM8-AL8 -> 3 | AN9: =AN8-AM8 -> 6 | ... VR9: =VR8-VQ8 -> 33 | VS9: 135 | VT9: =VT8-VS8 -> 0 | VU9: =VU8-VT8 -> 0 | VV9: =VV8-VU8 -> 37 | VW9: =VW8-VV8 -> 0 | VX9: =VX8-VW8 -> 0 | VY9: =VY8-VX8 -> 0 | VZ9: =VZ8-VY8 -> 0 | WA9: =WA8-VZ8 -> 107 | ... WH9: =WH8-WG8 -> 0 | WI9: 11 | WJ9: =WJ8-WI8 -> 117 | WK9: =WK8-WJ8 -> 0 | WL9: =WL8-WK8 -> 0 | WM9: =WM8-WL8 -> 0 | WN9: =WN8-WM8 -> 834 | WO9: =WO8-WN8 -> 237 | WP9: 40 | WQ9: =WQ8-WP8 -> 0 | WR9: =WR8-WQ8 -> 584 | WS9: =WS8-WR8 -> 70 | WT9: =WT8-WS8 -> 199 | WU9: =WU8-WT8 -> -1 | WV9: =WV8-WU8 -> 0 | WW9: =WW8-WV8 -> 188 | WX9: =WX8-WW8 -> 44 | ... YB9: =YB8-YA8 -> 0 | YC9: 0 | YD9: =YD8-YC8 -> 0 | YE9: =YE8-YD8 -> 0 | YF9: =YF8-YE8 -> 0 | YG9: =YG8-YF8 -> 0 | YH9: =YH8-YG8 -> 0 | YI9: =YI8-YH8 -> 0 | YJ9: =YJ8-YI8 -> -1 | YK9: =YK8-YJ8 -> 0 | ... YM9: =YM8-YL8 -> 0
B10: Growth | C10: =C8/296-1 -> 0.23986486 | D10: =D8/C8-1 -> 0 | E10: =E8/D8-1 -> 0.016348774 | F10: =F8/E8-1 -> 0.0080428954 | G10: =G8/F8-1 -> 0 | H10: =H8/G8-1 -> 0 | I10: =I8/H8-1 -> 0.026595745 | J10: =J8/I8-1 -> 0.025906736 | K10: =K8/J8-1 -> 0.022727273 | ... AF10: =AF8/AE8-1 -> 0.001984127 | AG10: =IFERROR(AG8/AF8-1,"") -> 0.013861386 | AH10: =IFERROR(AH8/AG8-1,"") -> 0 | AI10: =IFERROR(AI8/AH8-1,"") -> 0 | AJ10: =IFERROR(AJ8/AI8-1,"") -> 0 | AK10: =IFERROR(AK8/AJ8-1,"") -> 0.021484375 | AL10: =IFERROR(AL8/AK8-1,"") -> 0.019120459 | AM10: =IFERROR(AM8/AL8-1,"") -> 0.0056285178 | AN10: =IFERROR(AN8/AM8-1,"") -> 0.01119403 | ... VR10: =IFERROR(VR8/VQ8-1,"") -> 0.002626343 | VS10: 0.010715987 | VT10: =IFERROR(VT8/VS8-1,"") -> 0 | VU10: =IFERROR(VU8/VT8-1,"") -> 0 | VV10: =IFERROR(VV8/VU8-1,"") -> 0.0029058352 | VW10: =IFERROR(VW8/VV8-1,"") -> 0 | VX10: =IFERROR(VX8/VW8-1,"") -> 0 | VY10: =IFERROR(VY8/VX8-1,"") -> 0 | VZ10: =IFERROR(VZ8/VY8-1,"") -> 0 | WA10: =IFERROR(WA8/VZ8-1,"") -> 0.0083790133 | ... WH10: =IFERROR(WH8/WG8-1,"") -> 0 | WI10: 0.00084168643 | WJ10: =IFERROR(WJ8/WI8-1,"") -> 0.0089449541 | WK10: =IFERROR(WK8/WJ8-1,"") -> 0 | WL10: =IFERROR(WL8/WK8-1,"") -> 0 | WM10: =IFERROR(WM8/WL8-1,"") -> 0 | WN10: =IFERROR(WN8/WM8-1,"") -> 0.063196181 | WO10: =IFERROR(WO8/WN8-1,"") -> 0.01689117 | WP10: 0.0028034763 | WQ10: =IFERROR(WQ8/WP8-1,"") -> 0 | WR10: =IFERROR(WR8/WQ8-1,"") -> 0.040816327 | WS10: =IFERROR(WS8/WR8-1,"") -> 0.0047005103 | WT10: =IFERROR(WT8/WS8-1,"") -> 0.013300361 | WU10: =IFERROR(WU8/WT8-1,"") -> -6.595871e-05 | WV10: =IFERROR(WV8/WU8-1,"") -> 0 | WW10: =IFERROR(WW8/WV8-1,"") -> 0.012401055 | WX10: =IFERROR(WX8/WW8-1,"") -> 0.002866823 | ... YB10: =IFERROR(YB8/YA8-1,"") -> 0 | YC10: 0 | YD10: =IFERROR(YD8/YC8-1,"") -> 0 | YE10: =IFERROR(YE8/YD8-1,"") -> 0 | YF10: =IFERROR(YF8/YE8-1,"") -> 0 | YG10: =IFERROR(YG8/YF8-1,"") -> 0 | YH10: =IFERROR(YH8/YG8-1,"") -> 0 | YI10: =IFERROR(YI8/YH8-1,"") -> 0 | YJ10: =IFERROR(YJ8/YI8-1,"") -> -6.1342167e-05 | YK10: =IFERROR(YK8/YJ8-1,"") -> 0 | ... YM10: =IFERROR(YM8/YL8-1,"") -> 0
B12: Daily Transacting Users | C12: 85 | D12: 72 | E12: 92 | F12: 95 | G12: 85 | H12: 79 | I12: 98 | J12: 91 | K12: 91 | L12: 95 | M12: 99 | N12: 85 | O12: 80 | P12: 107 | Q12: 114 | R12: 122 | S12: 113 | T12: 114 | U12: 97 | V12: 105 | W12: 107 | X12: 109 | Y12: 128 | Z12: 121 | AA12: 118 | AB12: 125 | AC12: 107 | AD12: 109 | AE12: 128 | AF12: 107 | AG12: 108 | AH12: 135 | AI12: 124 | AJ12: 96 | AK12: 110 | AL12: 139 | AM12: 129 | AN12: 116 | AO12: 131 | AP12: 118 | AQ12: 114 | AR12: 122 | AS12: 122 | AT12: 129 | AU12: 143 | AV12: 163 | AW12: 130 | AX12: 142 | AY12: 132 | AZ12: 144 | BA12: 145 | BB12: 140 | BC12: 148 | BD12: 142 | BE12: 148 | BF12: 126 | BG12: 118 | BH12: 145 | BI12: 140 | BJ12: 195 | BK12: 166 | BL12: 156 | BM12: 147 | BN12: 141 | BO12: 149 | BP12: 149 | BQ12: 149 | BR12: 140 | BS12: 137 | BT12: 132 | BU12: 130 | BV12: 127 | BW12: 166 | BX12: 173 | BY12: 149 | BZ12: 138 | CA12: 159 | CB12: 154 | CC12: 165 | CD12: 160 | CE12: 182 | CF12: 163 | CG12: 144 | CH12: 162 | CI12: 162 | CK12: 171 | CL12: 188 | CM12: 160 | CN12: 170 | CO12: 168 | CP12: 183 | CQ12: 169 | CR12: 193 | CS12: 192 | CT12: 187 | CU12: 178 | CV12: 165 | CW12: 178 | CX12: 193 | CY12: 174 | CZ12: 198 | DA12: 184 | DB12: 176 | DC12: 193 | DD12: 208 | DE12: 173 | DF12: 160 | DG12: 199 | DH12: 200 | DI12: 192 | DJ12: 196 | DK12: 210 | DL12: 202 | DM12: 194 | DN12: 216 | DO12: 232 | DP12: 192 | DQ12: 172 | DR12: 207 | DS12: 230 | DT12: 222 | DU12: 209 | DV12: 192 | DW12: 201 | DX12: 189 | DY12: 214 | DZ12: 224 | EA12: 215 | EB12: 228 | EC12: 214 | ED12: 180 | EE12: 180 | EF12: 208 | EG12: 237 | EH12: 236 | EI12: 249 | EJ12: 249 | EK12: 213 | EL12: 249 | EM12: 267 | EN12: 278 | EO12: 303 | EP12: 273 | EQ12: 256 | ER12: 228 | ES12: 265 | ET12: 253 | EU12: 270 | EV12: 279 | EW12: 274 | EX12: 309 | EY12: 270 | EZ12: 284 | FA12: 302 | FB12: 321 | FC12: 337 | FD12: 316 | FE12: 308 | FF12: 281 | FG12: 289 | FH12: 299 | FI12: 310 | FJ12: 315 | FK12: 355 | FL12: 343 | FM12: 312 | FN12: 322 | FO12: 310 | FP12: 369 | FQ12: 360 | FR12: 357 | FS12: 376 | FT12: 352 | FU12: 352 | FV12: 359 | FW12: 351 | FX12: 361 | FY12: 396 | FZ12: 363 | GA12: 350 | GB12: 366 | GC12: 368 | GD12: 376 | GE12: 382 | GF12: 415 | GG12: 388 | GH12: 390 | GI12: 323 | GJ12: 345 | GK12: 358 | GL12: 389 | GM12: 389 | GN12: 414 | GO12: 398 | GP12: 386 | GQ12: 417 | GR12: 412 | GS12: 422 | GT12: 442 | GU12: 438 | GV12: 361 | GW12: 363 | GX12: 360 | GY12: 364 | GZ12: 409 | HA12: 447 | HB12: 412 | HC12: 396 | HD12: 361 | HE12: 416 | HF12: 424 | HG12: 493 | HH12: 492 | HI12: 486 | HJ12: 409 | HK12: 392 | HL12: 430 | HM12: 442 | HN12: 445 | HO12: 469 | HP12: 455 | HQ12: 396 | HR12: 382 | HS12: 400 | HT12: 429 | HU12: 493 | HV12: 512 | HW12: 491 | HX12: 468 | HY12: 484 | HZ12: 517 | IA12: 538 | IB12: 502 | IC12: 502 | ID12: 486 | IE12: 474 | IF12: 413 | IG12: 467 | IH12: 486 | II12: 500 | IJ12: 516 | IK12: 532 | IL12: 605 | IM12: 568 | IN12: 555 | IO12: 568 | IP12: 591 | IQ12: 658 | IR12: 619 | IS12: 562 | IT12: 633 | IU12: 552 | IV12: 523 | IW12: 599 | IX12: 648 | IY12: 608 | IZ12: 651 | JA12: 596 | JB12: 608 | JC12: 616 | JD12: 600 | JE12: 632 | JF12: 599 | JG12: 531 | JH12: 566 | JI12: 538 | JJ12: 588 | JK12: 578 | JL12: 616 | JM12: 607 | JN12: 527 | JO12: 585 | JP12: 637 | JQ12: 655 | JR12: 641 | JS12: 682 | JT12: 670 | JU12: 626 | JV12: 627 | JW12: 613 | JX12: 609 | JY12: 643 | JZ12: 689 | KA12: 637 | KB12: 528 | KC12: 576 | KD12: 639 | KE12: 611 | KF12: 691 | KG12: 686 | KH12: 674 | KI12: 606 | KJ12: 646 | KK12: 611 | KL12: 610 | KM12: 594 | KN12: 653 | KO12: 633 | KP12: 587 | KQ12: 567 | KR12: 591 | KS12: 576 | KT12: 650 | KU12: 652 | KV12: 693 | KW12: 629 | KX12: 585 | KY12: 640 | KZ12: 590 | LA12: 735 | LB12: 775 | LC12: 640 | LD12: 660 | LE12: 752 | LF12: 654 | LG12: 679 | LH12: 674 | LI12: 758 | LJ12: 756 | LK12: 645 | LL12: 800 | LM12: 724 | LN12: 720 | LO12: 744 | LP12: 778 | LQ12: 733 | LR12: 711 | LS12: 638 | LT12: 727 | LU12: 781 | LV12: 788 | LW12: 812 | LX12: 779 | LY12: 841 | LZ12: 786 | MA12: 761 | MB12: 748 | MC12: 779 | MD12: 797 | ME12: 802 | MF12: 759 | MG12: 674 | MH12: 708 | MI12: 718 | MJ12: 730 | MK12: 760 | ML12: 739 | MM12: 747 | MN12: 710 | MO12: 737 | MP12: 759 | MQ12: 731 | MR12: 815 | MS12: 779 | MT12: 764 | MU12: 778 | MV12: 714 | MW12: 572 | MX12: 669 | MY12: 710 | MZ12: 695 | NA12: 668 | NB12: 684 | NC12: 684 | ND12: 626 | NE12: 737 | NF12: 747 | NG12: 735 | NH12: 721 | NI12: 641 | NJ12: 648 | NK12: 643 | NL12: 661 | NM12: 713 | NN12: 662 | NO12: 655 | NP12: 628 | NQ12: 622 | NR12: 686 | NS12: 694 | NT12: 755 | NU12: 776 | NV12: 673 | NW12: 667 | NX12: 716 | NY12: 657 | NZ12: 683 | OA12: 697 | OB12: 673 | OC12: 646 | OD12: 645 | OE12: 641 | OF12: 609 | OG12: 701 | OH12: 729 | OI12: 873 | OJ12: 809 | OK12: 735 | OL12: 701 | OM12: 732 | ON12: 729 | OO12: 783 | OP12: 746 | OQ12: 674 | OR12: 704 | OS12: 716 | OT12: 698 | OU12: 865 | OV12: 883 | OW12: 880 | OX12: 853 | OY12: 864 | OZ12: 841 | PA12: 860 | PB12: 875 | PC12: 971 | PD12: 910 | PE12: 901 | PF12: 831 | PG12: 833 | PH12: 914 | PI12: 1012 | PJ12: 1085 | PK12: 1181 | PL12: 1065 | PM12: 1095 | PN12: 999 | PO12: 1044 | PP12: 1025 | PQ12: 1058 | PR12: 990 | PS12: 892 | PT12: 867 | PU12: 899 | PV12: 909 | PW12: 974 | PX12: 1047 | PY12: 1091 | PZ12: 1027 | QA12: 1055 | QB12: 1100 | QC12: 1056 | QD12: 1116 | QE12: 1127 | QF12: 1100 | QG12: 1009 | QH12: 1041 | QI12: 991 | QJ12: 1003 | QK12: 1097 | QL12: 1166 | QM12: 1090 | QN12: 1049 | QO12: 1068 | QP12: 1382 | QQ12: 1172 | QR12: 1075 | QS12: 1311 | QT12: 1344 | QU12: 1262 | QV12: 1259 | QW12: 1281 | QX12: 1313 | QY12: 1258 | QZ12: 1300 | RA12: 1289 | RB12: 1217 | RC12: 1229 | RD12: 1271 | RE12: 1390 | RF12: 1430 | RG12: 1473 | RH12: 1443 | RI12: 1321 | RJ12: 1289 | RK12: 1283 | RL12: 1248 | RM12: 1327 | RN12: 1404 | RO12: 1385 | RP12: 1260 | RQ12: 1219 | RR12: 1199 | RS12: 1321 | RT12: 1529 | RU12: 1490 | RV12: 1459 | RW12: 1387 | RX12: 1389 | RY12: 1350 | RZ12: 1363 | SA12: 1356 | SB12: 1429 | SC12: 1510 | SD12: 1350 | SE12: 1259 | SF12: 1309 | SG12: 1349 | SH12: 1555 | SI12: 1541 | SJ12: 1605 | SK12: 1592 | SL12: 1457 | SM12: 1505 | SN12: 1467 | SO12: 1552 | SP12: 1612 | SQ12: 1594 | SR12: 1475 | SS12: 1431 | ST12: 1492 | SU12: 1468 | SV12: 1504 | SW12: 1502 | SX12: 1486 | SY12: 1781 | SZ12: 1694 | TA12: 1625 | TB12: 1597 | TC12: 1693 | TD12: 1859 | TE12: 1684 | TF12: 1534 | TG12: 1562 | TH12: 1531 | TI12: 1536 | TJ12: 1663 | TK12: 1645 | TL12: 1678 | TM12: 1636 | TN12: 1620 | TO12: 1724 | TP12: 1733 | TQ12: 1805 | TR12: 1823 | TS12: 1787 | TT12: 1555 | TU12: 1642 | TV12: 1570 | TW12: 1659 | TX12: 1704 | TY12: 1748 | TZ12: 1745 | UA12: 1551 | UB12: 1683 | UC12: 1963 | UD12: 1871 | UE12: 1962 | UF12: 1963 | UG12: 1931 | UH12: 1777 | UI12: 1820 | UJ12: 1719 | UK12: 1701 | UL12: 1708 | UM12: 1843 | UN12: 1787 | UO12: 1644 | UP12: 1654 | UQ12: 1838 | UR12: 1790 | US12: 1873 | UT12: 1961 | UU12: 1933 | UV12: 1733 | UW12: 1701 | UX12: 1715 | UY12: 1718 | UZ12: 1769 | VA12: 1862 | VB12: 1758 | VC12: 1648 | VD12: 1617 | VE12: 1610 | VF12: 1610 | VG12: 1714 | VH12: 1800 | VI12: 2294 | VJ12: 2136 | VK12: 1886 | VL12: 1828 | VM12: 1779 | VN12: 1832 | VO12: 1925 | VP12: 1998 | VQ12: 1795 | VR12: 1639 | VS12: 1675 | VT12: 1626 | VU12: 1703 | VV12: 1800 | VW12: 2146 | VX12: 2015 | VY12: 1750 | VZ12: 1691 | WA12: 1773 | WB12: 2052 | WC12: 2191 | WD12: 2254 | WE12: 2197 | WF12: 2003 | WG12: 1957 | WH12: 1885 | WI12: 1940 | WJ12: 1907 | WK12: 1974 | WL12: 2067 | WM12: 1996 | WN12: 2414 | WO12: 2302 | WP12: 2224 | WQ12: 2280 | WR12: 2434 | WS12: 2455 | WT12: 2291 | WU12: 2379 | WV12: 2480 | WW12: 2335 | WX12: 2500 | WY12: 2437 | WZ12: 2451 | XA12: 2288 | XB12: 2314 | XC12: 2450 | XD12: 2425 | XE12: 2543 | XF12: 2573 | XG12: 2644 | XH12: 2382 | XI12: 2315 | XJ12: 2448 | XK12: 2448 | XL12: 2553 | XM12: 2634 | XN12: 2553 | XO12: 2311 | XP12: 2342 | XQ12: 2504 | XR12: 2754 | XS12: 2708 | XT12: 2858 | XU12: 2710 | XV12: 2494 | XW12: 2483 | XX12: 2471 | XY12: 2460 | XZ12: 2631 | YA12: 2757 | YB12: 2607 | YC12: 2300 | YD12: 2250 | YE12: 2296 | YF12: 2495 | YG12: 2700 | YH12: 2817 | YI12: 2864 | YJ12: 2509 | YK12: 2470 | YL12: 2483 | YM12: 2452
B13: Growth | C13: =C12/296-1 -> -0.71283784 | D13: =D12/C12-1 -> -0.15294118 | E13: =E12/D12-1 -> 0.27777778 | F13: =F12/E12-1 -> 0.032608696 | G13: =G12/F12-1 -> -0.10526316 | H13: =H12/G12-1 -> -0.070588235 | I13: =I12/H12-1 -> 0.24050633 | J13: =J12/I12-1 -> -0.071428571 | K13: =K12/J12-1 -> 0 | ... AF13: =AF12/AE12-1 -> -0.1640625 | AG13: =IFERROR(AG12/AF12-1,"") -> 0.0093457944 | AH13: =IFERROR(AH12/AG12-1,"") -> 0.25 | AI13: =IFERROR(AI12/AH12-1,"") -> -0.081481481 | AJ13: =IFERROR(AJ12/AI12-1,"") -> -0.22580645 | AK13: =IFERROR(AK12/AJ12-1,"") -> 0.14583333 | AL13: =IFERROR(AL12/AK12-1,"") -> 0.26363636 | AM13: =IFERROR(AM12/AL12-1,"") -> -0.071942446 | AN13: =IFERROR(AN12/AM12-1,"") -> -0.10077519 | ... VR13: =IFERROR(VR12/VQ12-1,"") -> -0.086908078 | VS13: 0.021964613 | VT13: =IFERROR(VT12/VS12-1,"") -> -0.029253731 | VU13: =IFERROR(VU12/VT12-1,"") -> 0.047355474 | VV13: =IFERROR(VV12/VU12-1,"") -> 0.056958309 | VW13: =IFERROR(VW12/VV12-1,"") -> 0.19222222 | VX13: =IFERROR(VX12/VW12-1,"") -> -0.061043802 | VY13: =IFERROR(VY12/VX12-1,"") -> -0.13151365 | VZ13: =IFERROR(VZ12/VY12-1,"") -> -0.033714286 | WA13: =IFERROR(WA12/VZ12-1,"") -> 0.048492017 | ... WH13: =IFERROR(WH12/WG12-1,"") -> -0.036791007 | WI13: 0.029177719 | WJ13: =IFERROR(WJ12/WI12-1,"") -> -0.017010309 | WK13: =IFERROR(WK12/WJ12-1,"") -> 0.035133718 | WL13: =IFERROR(WL12/WK12-1,"") -> 0.047112462 | WM13: =IFERROR(WM12/WL12-1,"") -> -0.034349299 | WN13: =IFERROR(WN12/WM12-1,"") -> 0.20941884 | WO13: =IFERROR(WO12/WN12-1,"") -> -0.046396023 | WP13: -0.033883579 | WQ13: =IFERROR(WQ12/WP12-1,"") -> 0.025179856 | WR13: =IFERROR(WR12/WQ12-1,"") -> 0.06754386 | WS13: =IFERROR(WS12/WR12-1,"") -> 0.0086277732 | WT13: =IFERROR(WT12/WS12-1,"") -> -0.066802444 | WU13: =IFERROR(WU12/WT12-1,"") -> 0.038411174 | WV13: =IFERROR(WV12/WU12-1,"") -> 0.042454813 | WW13: =IFERROR(WW12/WV12-1,"") -> -0.058467742 | WX13: =IFERROR(WX12/WW12-1,"") -> 0.070663812 | ... YB13: =IFERROR(YB12/YA12-1,"") -> -0.054406964 | YC13: -0.12 | YD13: =IFERROR(YD12/YC12-1,"") -> -0.02173913 | YE13: =IFERROR(YE12/YD12-1,"") -> 0.020444444 | YF13: =IFERROR(YF12/YE12-1,"") -> 0.086672474 | YG13: =IFERROR(YG12/YF12-1,"") -> 0.082164329 | YH13: =IFERROR(YH12/YG12-1,"") -> 0.043333333 | YI13: =IFERROR(YI12/YH12-1,"") -> 0.016684416 | YJ13: =IFERROR(YJ12/YI12-1,"") -> -0.12395251 | YK13: =IFERROR(YK12/YJ12-1,"") -> -0.015544041 | ... YM13: =IFERROR(YM12/YL12-1,"") -> -0.012484897
B15: Transact Rate | C15: =C12/C8 -> 0.23160763 | D15: =D12/D8 -> 0.19618529 | E15: =E12/E8 -> 0.24664879 | F15: =F12/F8 -> 0.25265957 | G15: =G12/G8 -> 0.22606383 | H15: =H12/H8 -> 0.21010638 | I15: =I12/I8 -> 0.25388601 | J15: =J12/J8 -> 0.22979798 | ... WH15: =WH12/WH8 -> 0.14423445 | WI15: 0.14831804 | WJ15: =WJ12/WJ8 -> 0.14450254 | WK15: =WK12/WK8 -> 0.14957945 | WL15: =WL12/WL8 -> 0.15662651 | WM15: =WM12/WM8 -> 0.1512465 | WN15: =WN12/WN8 -> 0.17204761 | WO15: =WO12/WO8 -> 0.16134006 | WP15: 0.15543752 | WQ15: =WQ12/WQ8 -> 0.15935141 | WR15: =WR12/WR8 -> 0.16344346 | WS15: =WS12/WS8 -> 0.16408234 | WT15: =WT12/WT8 -> 0.1511114 | WU15: =WU12/WU8 -> 0.15692612 | WV15: =WV12/WV8 -> 0.16358839 | WW15: =WW12/WW8 -> 0.15213709 | WX15: =WX12/WX8 -> 0.16242204 | ... YB15: =YB12/YB8 -> 0.15991903 | YC15: 0.141 | YD15: =YD12/YD8 -> 0.13801987 | YE15: =YE12/YE8 -> 0.14084161 | YF15: =YF12/YF8 -> 0.15304871 | YG15: =YG12/YG8 -> 0.16562385 | YH15: =YH12/YH8 -> 0.17280088 | YI15: =YI12/YI8 -> 0.17568397 | YJ15: =YJ12/YJ8 -> 0.15391694 | YK15: =YK12/YK8 -> 0.15152445 | ... YM15: =YM12/YM8 -> 0.15042022
B18: Gross Transaction Volume (GTV)
B19: Transaction Value | C19: 486965.33 | D19: 738869.58 | E19: 373364.62 | F19: 443005.49 | G19: 220729.95 | H19: 367007.18 | I19: 689649.58 | J19: 302217.47 | K19: 366689.26 | L19: 346122.45 | M19: 460807.93 | N19: 326748.02 | O19: 315842.28 | P19: 236066.14 | Q19: 954450.41 | R19: 820996.79 | S19: 795837.43 | T19: 700276.06 | U19: 340449.98 | V19: 472914.8 | W19: 455883.24 | X19: 331977.14 | Y19: 454052.38 | Z19: 445666.32 | AA19: 453871.03 | AB19: 377065.95 | AC19: 289043.17 | AD19: 350666.06 | AE19: 409193.83 | AF19: 392536.51 | AG19: 546421.06 | AH19: 546601.2 | AI19: 883585.55 | AJ19: 404135.64 | AK19: 398796.36 | AL19: 580799.63 | AM19: 439350.91 | AN19: 374546.47 | AO19: 348506.46 | AP19: 500609.78 | AQ19: 379108.34 | AR19: 400463.92 | AS19: 476621.53 | AT19: 1005233.8 | AU19: 1010463.2 | AV19: 757517.89 | AW19: 401468.48 | AX19: 699155.92 | AY19: 501073.22 | AZ19: 441040.35 | BA19: 591282.11 | BB19: 323227.22 | BC19: 832247.37 | BD19: 434876.56 | BE19: 391249.15 | BF19: 349493.61 | BG19: 331500.29 | BH19: 648781.05 | BI19: 937932.06 | BJ19: 902173.95 | BK19: 794930.13 | BL19: 636792.89 | BM19: 494048.23 | BN19: 306826.31 | BO19: 714120.01 | BP19: 551460.07 | BQ19: 577631.04 | BR19: 584819.18 | BS19: 548078.59 | BT19: 405741.14 | BU19: 375212.17 | BV19: 542091.54 | BW19: 694490.25 | BX19: 942228.8 | BY19: 441709.26 | BZ19: 498801.51 | CA19: 403821.7 | CB19: 523255.6 | CC19: 965037.02 | CD19: 530923.31 | CE19: 730623.09 | CF19: 621300.57 | CG19: 426415.31 | CH19: 698645.92 | CI19: 656329.8 | CJ19: 387304.82 | CK19: 580402.73 | CL19: 681585.98 | CM19: 491101.49 | CN19: 703392.77 | CO19: 615387.05 | CP19: 1039585.1 | CQ19: 677731.06 | CR19: 519403.33 | CS19: 730015.3 | CT19: 844208.41 | CU19: 720005.68 | CV19: 671677.47 | CW19: 859573.42 | CX19: 713368.24 | CY19: 1074529.6 | CZ19: 889184.67 | DA19: 555501.26 | DB19: 635067.78 | DC19: 966554.16 | DD19: 663627.56 | DE19: 653116.03 | DF19: 733655.3 | DG19: 696131.67 | DH19: 771901.34 | DI19: 678340.34 | DJ19: 691962.22 | DK19: 1045628.1 | DL19: 682075.43 | DM19: 600434.79 | DN19: 732022.43 | DO19: 739517.38 | DP19: 482804.8 | DQ19: 595112.65 | DR19: 788646.53 | DS19: 999406.21 | DT19: 1560862.4 | DU19: 731949.6 | DV19: 673987.43 | DW19: 580686.05 | DX19: 643608.8 | DY19: 684490.65 | DZ19: 643145.28 | EA19: 972975.55 | EB19: 785943.15 | EC19: 920839.43 | ED19: 571283.49 | EE19: 387231.98 | EF19: 710564.8 | EG19: 964571.95 | EH19: 935924.24 | EI19: 1157775.5 | EJ19: 693597.93 | EK19: 793081.16 | EL19: 688057.77 | EM19: 920395.38 | EN19: 871818.32 | EO19: 1222228.9 | EP19: 857527.47 | EQ19: 880900.49 | ER19: 643933.7 | ES19: 1040412.3 | ET19: 554857.92 | EU19: 749159.19 | EV19: 1051763.4 | EW19: 937606.86 | EX19: 1488863.2 | EY19: 1250456.4 | EZ19: 882241.18 | FA19: 1117198.7 | FB19: 1169676.4 | FC19: 1045536 | FD19: 1237422.8 | FE19: 983814.96 | FF19: 895694.52 | FG19: 882684.63 | FH19: 802234.51 | FI19: 820559.93 | FJ19: 1054346 | FK19: 1441216.1 | FL19: 1142915.2 | FM19: 973092.18 | FN19: 964616.47 | FO19: 786624.71 | FP19: 1222767.1 | FQ19: 1187846.7 | FR19: 794152.17 | FS19: 981306.9 | FT19: 1165643.3 | FU19: 1274836.8 | FV19: 1606343 | FW19: 1431790.6 | FX19: 938809.81 | FY19: 1224095.3 | FZ19: 1144190.7 | GA19: 1341434.8 | GB19: 1632277 | GC19: 1723121.3 | GD19: 1133542 | GE19: 1101832.3 | GF19: 1401841.5 | GG19: 1103935.8 | GH19: 1439733.6 | GI19: 760733.32 | GJ19: 1241937.9 | GK19: 951413.91 | GL19: 1116166.1 | GM19: 993967.8 | GN19: 1176532.8 | GO19: 1157589.8 | GP19: 1285617.8 | GQ19: 1344951.8 | GR19: 1232907.1 | GS19: 1531590.5 | GT19: 1686738.2 | GU19: 1492859.6 | GV19: 1480551.9 | GW19: 1999085.2 | GX19: 1632685.2 | GY19: 1118538 | GZ19: 1529433.1 | HA19: 1426697.7 | HB19: 1089392.3 | HC19: 1080402.1 | HD19: 1048937.4 | HE19: 1188979 | HF19: 1467224.6 | HG19: 1733015.5 | HH19: 2062945.6 | HI19: 1352606.7 | HJ19: 1201048.6 | HK19: 1352498.2 | HL19: 1265272.1 | HM19: 1960688.8 | HN19: 1715612.2 | HO19: 1253644.3 | HP19: 1131606.4 | HQ19: 1299273.6 | HR19: 1187087.2 | HS19: 1163033.6 | HT19: 1312912.2 | HU19: 2072277.4 | HV19: 1623393 | HW19: 1349656.5 | HX19: 1566720.1 | HY19: 1845014.7 | HZ19: 1258505.6 | IA19: 1477296.5 | IB19: 1705202.8 | IC19: 1387264 | ID19: 1148453.4 | IE19: 1261402.6 | IF19: 1730745.9 | IG19: 1490020.6 | IH19: 1568398.3 | II19: 1615169.4 | IJ19: 1695200 | IK19: 1945191.9 | IL19: 2917753.1 | IM19: 2483959.8 | IN19: 1853784.6 | IO19: 1572693.9 | IP19: 1734692.8 | IQ19: 1995113.9 | IR19: 1892993.9 | IS19: 1353565.6 | IT19: 1824923.8 | IU19: 1478167.7 | IV19: 1364312.6 | IW19: 2134268.7 | IX19: 2471938.4 | IY19: 2346566 | IZ19: 2329959.5 | JA19: 1728006.2 | JB19: 1597154.6 | JC19: 2729112.6 | JD19: 1695374.6 | JE19: 2001244.4 | JF19: 1824981.8 | JG19: 1595446.2 | JH19: 1662668.4 | JI19: 1651203.6 | JJ19: 2042606.5 | JK19: 1959518.8 | JL19: 1978334.8 | JM19: 1875258.4 | JN19: 1598060.3 | JO19: 2084870.7 | JP19: 2824176.7 | JQ19: 2738023.2 | JR19: 2312554.7 | JS19: 2725405.3 | JT19: 2294740.3 | JU19: 1973825.5 | JV19: 2113553.8 | JW19: 1690822.5 | JX19: 2313588.9 | JY19: 2304185.4 | JZ19: 2150146.7 | KA19: 1837257.1 | KB19: 1529567.8 | KC19: 2136338.9 | KD19: 2843226.6 | KE19: 2102590.2 | KF19: 2447742.3 | KG19: 2447700.1 | KH19: 1756277.1 | KI19: 2010379.2 | KJ19: 1925266.7 | KK19: 1849821.9 | KL19: 1440221.8 | KM19: 1686376.6 | KN19: 1996732.4 | KO19: 1816037.8 | KP19: 1471707.1 | KQ19: 1914670.1 | KR19: 1953329.1 | KS19: 1918566.6 | KT19: 2492820.2 | KU19: 2142954.5 | KV19: 3022015 | KW19: 3175373.6 | KX19: 1927245.6 | KY19: 2113800 | KZ19: 1938402.1 | LA19: 2754021.1 | LB19: 2619611.5 | LC19: 2063729.9 | LD19: 2078589.1 | LE19: 2264095.2 | LF19: 2108360.7 | LG19: 1645485.1 | LH19: 2140303.6 | LI19: 2505513.4 | LJ19: 3125347.3 | LK19: 1821576 | LL19: 2189308.1 | LM19: 1997825.1 | LN19: 2134807.6 | LO19: 2231888.2 | LP19: 2526357.1 | LQ19: 2283908.1 | LR19: 2133846.4 | LS19: 1604626.2 | LT19: 2255672.3 | LU19: 2410482.9 | LV19: 2574686 | LW19: 2675531.8 | LX19: 2292985.8 | LY19: 3120013.4 | LZ19: 3009562.9 | MA19: 1946899.8 | MB19: 2185330.5 | MC19: 2920019.5 | MD19: 2824735.3 | ME19: 2457400.6 | MF19: 2770922.3 | MG19: 1747307.1 | MH19: 1911890.2 | MI19: 1774786.8 | MJ19: 2647221.9 | MK19: 2276988.7 | ML19: 2252713.7 | MM19: 2598717.9 | MN19: 1899759.7 | MO19: 2002427.8 | MP19: 2970569.2 | MQ19: 2011528 | MR19: 2452514.4 | MS19: 2431497.5 | MT19: 2266997.6 | MU19: 2923173.3 | MV19: 2079236.6 | MW19: 1513098.2 | MX19: 2272224.4 | MY19: 2151079 | MZ19: 1834047.1 | NA19: 2456075.8 | NB19: 2339871.9 | NC19: 2410583.4 | ND19: 1954157.3 | NE19: 2665578.4 | NF19: 2516920.5 | NG19: 2258359.5 | NH19: 1751160.9 | NI19: 1916842.3 | NJ19: 1566346 | NK19: 1665154.9 | NL19: 2122402.2 | NM19: 1957906 | NN19: 1708319.6 | NO19: 1572339.1 | NP19: 2024261.7 | NQ19: 1952894.9 | NR19: 2134012.4 | NS19: 1942789.6 | NT19: 2020200.2 | NU19: 2304114.1 | NV19: 2383414.8 | NW19: 1895364.8 | NX19: 2081594 | NY19: 1790375 | NZ19: 2610723.8 | OA19: 2089192.4 | OB19: 1981472.6 | OC19: 1565992.8 | OD19: 1942576.5 | OE19: 1686172.9 | OF19: 1495248.6 | OG19: 2233972.6 | OH19: =2495799.69+3908.59 -> 2499708.3 | OI19: 3109991.9 | OJ19: 3180800.7 | OK19: 1972039.6 | OL19: 2524502.2 | OM19: 2103249.4 | ON19: 2019153.2 | OO19: 2059476.1 | OP19: 1755323.8 | OQ19: 1611170 | OR19: 1840735 | OS19: 1510110.6 | OT19: 1773107.9 | OU19: 2354001.1 | OV19: 3353547.7 | OW19: 2869968.6 | OX19: 2687367.9 | OY19: 2711081.7 | OZ19: 2509137 | PA19: 2160720.3 | PB19: 2179221.5 | PC19: 2179221.5 | PD19: 2469121 | PE19: 2514430.2 | PF19: 2275260.7 | PG19: 2127917.4 | PH19: 2128903.6 | PI19: 2940353 | PJ19: 2995858.1 | PK19: 4237504.9 | PL19: 4362645.9 | PM19: 3727954.5 | PN19: 2350612.7 | PO19: 3253176 | PP19: 3025832.1 | PQ19: 2981744.1 | PR19: 2709087.4 | PS19: 2075891.1 | PT19: 2698725 | PU19: 2028983.3 | PV19: 2248955.1 | PW19: 2960128.1 | PX19: 3368052.1 | PY19: 3575052.8 | PZ19: 7309518.5 | QA19: 3510551.5 | QB19: 3629961.2 | QC19: 3678928.2 | QD19: 3648604.8 | QE19: 3568144.5 | QF19: 3418952.5 | QG19: 2527710.6 | QH19: 3123644.3 | QI19: 3066609.9 | QJ19: 3091554 | QK19: 3373651.6 | QL19: 3692421.5 | QM19: 3835660.4 | QN19: 3437370.5 | QO19: 3758759.5 | QP19: 4714997.1 | QQ19: 4660289.9 | QR19: 3467455.5 | QS19: 4964454.8 | QT19: 4525886.9 | QU19: 3985719.1 | QV19: 3893229.7 | QW19: 3765745.9 | QX19: 3627239.9 | QY19: 4136936.3 | QZ19: 3395542.4 | RA19: 3189777.8 | RB19: 3361512.2 | RC19: 4146259.7 | RD19: 3855631.3 | RE19: 4650720.7 | RF19: 4926484.1 | RG19: 4550421.7 | RH19: 3923048.1 | RI19: 3621596.7 | RJ19: 3433692 | RK19: 3244171.8 | RL19: 3115660.1 | RM19: 3411695.2 | RN19: 4087389.2 | RO19: 3778955.6 | RP19: 2672720.6 | RQ19: 3166996.9 | RR19: 3545424.9 | RS19: 3339818.4 | RT19: 5358819.7 | RU19: 5991618.5 | RV19: 4249590.1 | RW19: 3796239.6 | RX19: 4125727.6 | RY19: 3677925.9 | RZ19: 3555790.4 | SA19: 4306045.4 | SB19: 3876158.3 | SC19: 3909798 | SD19: 3400020.4 | SE19: 2950045.5 | SF19: 3400559.9 | SG19: 3687767.3 | SH19: 4912717.3 | SI19: 4506329.7 | SJ19: 4932004.4 | SK19: 4788303 | SL19: 3849321.6 | SM19: 4482896.4 | SN19: 3736580.6 | SO19: 3761675.6 | SP19: 5037785.2 | SQ19: 4516926.4 | SR19: 4516926.4 | SS19: 3599580.3 | ST19: 4063939.7 | SU19: 3811666.8 | SV19: 4398957.3 | SW19: 4703359.3 | SX19: 4244742 | SY19: 5963055.4 | SZ19: 6460125.2 | TA19: 4681671.9 | TB19: 4406227.5 | TC19: 6175099.3 | TD19: 6231211.8 | TE19: 5356027.2 | TF19: 4561817.4 | TG19: 4594434.7 | TH19: 4003443.1 | TI19: 3974171.5 | TJ19: 4674624.3 | TK19: 4060299.7 | TL19: 4655263.4 | TM19: 4591014.7 | TN19: 4921025.2 | TO19: 4920065.2 | TP19: 4410735.2 | TQ19: 4763511.5 | TR19: 5283480.9 | TS19: 4515851.5 | TT19: 4357709.6 | TU19: 4235436.3 | TV19: 3961838.9 | TW19: 4238301.5 | TX19: 4385970.3 | TY19: 4682057 | TZ19: 3897476.5 | UA19: 3753498.5 | UB19: 4148573.1 | UC19: 5653317.7 | UD19: 5240166.2 | UE19: 5355702 | UF19: 5522573.8 | UG19: 5019114.6 | UH19: 5705157 | UI19: 5042324.7 | UJ19: 4133008.5 | UK19: 3992743.3 | UL19: 4841635.8 | UM19: 4833177 | UN19: 4405963.9 | UO19: 3438279.6 | UP19: 4011951.7 | UQ19: 5264691.7 | UR19: 5631755.8 | US19: 5050902.3 | UT19: 5171299.4 | UU19: 4952825.7 | UV19: 3933857.1 | UW19: 4318635.3 | UX19: 3932175.8 | UY19: 3552169.2 | UZ19: 3985107.4 | VA19: 5022294.4 | VB19: 4056665 | VC19: 3900577.4 | VD19: 3786236 | VE19: 3454550.7 | VF19: 3454550.7 | VG19: 4079155.6 | VH19: 4029801.4 | VI19: 7573095.7 | VJ19: 6167538.4 | VK19: 5236170.1 | VL19: 4496363.5 | VM19: 4471961.8 | VN19: 4611360.5 | VO19: 4830436.6 | VP19: 5772307 | VQ19: 4181665.5 | VR19: 3879750.6 | VS19: 4054676.7 | VT19: 3499167.2 | VU19: 3829243.2 | VV19: 4348430 | VW19: 5941730.2 | VX19: 5346318.8 | VY19: 3890967.2 | VZ19: 4512766.9 | WA19: 5114057.2 | WB19: 5196847.9 | WC19: 5571510.5 | WD19: 5673369.8 | WE19: 5682309.1 | WF19: 4951735.7 | WG19: 5031483.4 | WH19: 4487256.7 | WI19: 5070233.7 | WJ19: 4568358 | WK19: 5968469 | WL19: 6257099.7 | WM19: 5441316.6 | WN19: 7022681.7 | WO19: 5718049 | WP19: 6115728.3 | WQ19: 6119048.2 | WR19: 6630173.4 | WS19: 6757620.7 | WT19: 5956084 | WU19: 6889025.9 | WV19: 6528092.5 | WW19: 5358250.5 | WX19: 6994256 | WY19: 6462652.4 | WZ19: 6461225.8 | XA19: 6130756.4 | XB19: 5572566.7 | XC19: 6803575.4 | XD19: 6467348.6 | XE19: 7351547 | XF19: 6655994.4 | XG19: 7098318.1 | XH19: 6430080.5 | XI19: 5985488.8 | XJ19: 6159124.2 | XK19: 6865943.8 | XL19: 7059418.3 | XM19: 6960912.2 | XN19: 6725805 | XO19: 5803765.5 | XP19: 6264378.3 | XQ19: 6432724 | XR19: 8402753.6 | XS19: 7694928.6 | XT19: 8087580.6 | XU19: 7740220.4 | XV19: 7065263.3 | XW19: 6623169.8 | XX19: 6490840.6 | XY19: 7532992.9 | XZ19: 7832729.2 | YA19: 7863513.4 | YB19: 7491364.2 | YC19: 6076238 | YD19: 6561041.9 | YE19: 5713854.2 | YF19: 7328780.3 | YG19: 8213389.2 | YH19: 7950245.9 | YI19: 7625321.8 | YJ19: 7280168.5 | YK19: 6830951.3 | YL19: 6296790.7 | YM19: 5765360.3
